Workbook
Name cogs1: '[1]Income Statment'!$D$5
Name cogs2: '[1]Income Statment'!$E$5
Name cogs3: '[1]Income Statment'!$F$5
Name invent1: '[1]Financial Statment'!$E$8
Name invent2: '[1]Financial Statment'!$F$8
Name invent3: '[1]Financial Statment'!$G$8
Name payab1: '[1]Financial Statment'!$E$21
Name payab2: '[1]Financial Statment'!$F$21
Name payab3: '[1]Financial Statment'!$G$21
Name receiv1: '[1]Financial Statment'!$E$7
Name receiv2: '[1]Financial Statment'!$F$7
Name receiv3: '[1]Financial Statment'!$G$7
Name sales1: '[1]Income Statment'!$D$4
Name sales2: '[1]Income Statment'!$E$4
Name sales3: '[1]Income Statment'!$F$4
Name switch: [2]Info!$N$10

Sheet Main Model
A1: Projections Model
B3: Year | C3: 2016A | D3: 2022A | E3: 2023A | F3: 2024A | G3: 2025E | H3: 2026E | I3: 2027E | J3: 2028E
B4: GULF PACKAGING INDUSTRIES LTD | D4: His | E4: His | F4: His | G4: Proj | H4: Proj | I4: Proj | J4: Proj
B5: Switch | C5: 1
A7: Income Statement Assumptions
B8: 4Y CAGR Revenue
B9: Revenue growth | C9: 0 | D9: 0.05 | E9: =(E49/D49)-1 -> -0.24780895 | F9: =(F49/E49)-1 -> 0.4712745 | G9: 0 | H9: 0.04 | I9: 0.04 | J9: 0.02
B10: COGS % revenues | D10: =D50/D49 -> 0.69775449 | E10: =E50/E49 -> 0.85464686 | F10: =F50/F49 -> 0.81523921 | G10: 0.8 | H10: =G10 -> 0.8 | I10: =H10 -> 0.8 | J10: =I10 -> 0.8
B11: SG&A % revenues | D11: =D52/D$49 -> 0.13451303 | E11: =E52/E$49 -> 0.13160358 | F11: =F52/F$49 -> 0.13660525 | G11: 0.12 | H11: 0.12 | I11: 0.12 | J11: 0.12
B12: Depreciation % beginning net PP&E | D12: =D54/D$71 -> 0.058479507 | E12: =E54/E$71 -> 0.065921209 | F12: =F54/F$71 -> 0.084819865 | G12: =AVERAGE(D12:F12) -> 0.069740194 | H12: =AVERAGE(E12:G12) -> 0.073493756 | I12: =AVERAGE(F12:H12) -> 0.076017938 | J12: =AVERAGE(G12:I12) -> 0.073083963
B13: Other non operating (income) / expense | D13: =D58/D$49 -> -0.0019971879 | E13: =E58/E$49 -> -0.011301223 | F13: =F58/F$49 -> -0.0082112354 | G13: =AVERAGE(D13:F13) -> -0.007169882 | H13: =AVERAGE(E13:G13) -> -0.0088941133 | I13: =AVERAGE(F13:H13) -> -0.0080917435 | J13: =AVERAGE(G13:I13) -> -0.0080519129
B14: Zakt % | D14: =D59/(D53-D57-D58) -> 0.019012338 | E14: =E59/(E53-E57-E58) -> -0.093184717 | F14: =F59/(F53-F57-F58) -> 0.027968913 | G14: 0.07 | H14: 0.07 | I14: 0.07 | J14: 0.07
B15: Dividend % Net income | D15: =D61/D60 -> 1.0028189 | E15: =E61/E60 -> 0 | F15: =F61/F60 -> 0 | G15: 0 | H15: 0 | I15: 0 | J15: 0.5
A17: Balance Sheet/CF Assumptions
B18: Receivable days | D18: =D163 -> 93.367882 | E18: =E163 -> 109.49731 | F18: =F163 -> 73.285285 | G18: 73 | H18: 73 | I18: 73 | J18: 73
B19: Inventory days | D19: =D164 -> 55.186129 | E19: =E164 -> 77.645546 | F19: =F164 -> 68.027912 | G19: 68 | H19: 68 | I19: 68 | J19: 68
B20: Payable days | D20: =D165 -> 21.031745 | E20: =E165 -> 24.376041 | F20: =F165 -> 20.657445 | G20: 22 | H20: 22 | I20: 22 | J20: 22
B21: Other current assets % revenues | D21: =(D68)/D$49 -> 0.079650072 | E21: =(E68)/E$49 -> 0.097318551 | F21: =(F68)/F$49 -> 0.013807064 | G21: 0.04 | H21: 0.04 | I21: 0.04 | J21: 0.04
B22: Due from related % revenues | D22: =(D67)/D$49 -> 0.041859309 | E22: =(E67)/E$49 -> 1.7848524e-05 | F22: =(F67)/F$49 -> 0.004939022 | G22: 0.005 | H22: 0.005 | I22: 0.02 | J22: 0.02
B23: Other Current liabilities % revenue | D23: =D78/D$49 -> 0.11186513 | E23: =E78/E$49 -> 0.14636314 | F23: =F78/F$49 -> 0.1037026 | G23: 0.1037026 | H23: 0.1037026 | I23: 0.1037026 | J23: 0.1037026
B24: Capex % revenues | D24: =D34/D49 -> 0.3108844 | E24: =E34/E49 -> 0.15138489 | F24: =F34/F49 -> 0.04090155 | G24: 0.065 | H24: 0.065 | I24: 0.05 | J24: 0.05
B25: Intangible Assets % revenues | D25: =D72/D49 -> 0.0043569034 | E25: =E72/E49 -> 0.0056640027 | F25: =F72/F49 -> 0.0031978587 | G25: 0.0031978587 | H25: 0.0031978587 | I25: 0.0031978587 | J25: 0.0031978587
B26: Other long term assets % revenues | D26: =D73/D$49 -> 0.0027679325 | E26: =E73/E$49 -> 0.0026564154 | F26: =F73/F$49 -> 0.0013031244 | G26: =AVERAGE(D26:F26) -> 0.0022424908 | H26: =AVERAGE(E26:G26) -> 0.0020673435 | I26: =AVERAGE(F26:H26) -> 0.0018709862 | J26: =AVERAGE(G26:I26) -> 0.0020602735
B27: Other non current liabilities % revenues | D27: =D82/D$49 -> 0.020300059 | E27: =E82/E$49 -> 0.027588808 | F27: =F82/F$49 -> 0.01975448 | G27: 0.03 | H27: =G27 -> 0.03 | I27: =H27 -> 0.03 | J27: =I27 -> 0.03
A31: Balance Sheet Calculations
D32: =D48 -> 2022 | E32: =E48 -> 2023 | F32: =F48 -> 2024 | G32: =G48 -> 2025 | H32: =H48 -> 2026 | I32: =I48 -> 2027 | J32: =J48 -> 2028
B33: Beg. PPE | D33: 247178701 | E33: =D36 -> 504227333 | F33: =E36 -> 571504943 | G33: =F36 -> 565277861 | H33: =G36 -> 5.9120306e+08 | I33: =H36 -> 6.1575313e+08 | J33: =I36 -> 6.231542e+08
B34: Capex | D34: =D36-D33+D35 -> 286535598 | E34: =E36-E33+E35 -> 104951907 | F34: =F36-F33+F35 -> 41719710 | G34: =G24*G49 -> 66300205 | H34: =H24*H49 -> 68952214 | I34: =I24*I49 -> 55161771 | J34: =J24*J49 -> 56265006 | K34: =F34/G33 -> 0.073803899
B35: Dep. | D35: =D54 -> 29486966 | E35: =E54 -> 37674297 | F35: =F54 -> 47946792 | G35: =G12*G33 -> 39422588 | H35: =H12*H33 -> 43449734 | I35: =I12*I33 -> 46808284 | J35: =J12*J33 -> 45542579
B36: Ending PPE | D36: =D71 -> 504227333 | E36: =E71 -> 571504943 | F36: =F71 -> 565277861 | G36: =G33+G34-G35-G55 -> 5.9120306e+08 | H36: =H33+H34-H35-H55 -> 6.1575313e+08 | I36: =I33+I34-I35-I55 -> 6.231542e+08 | J36: =J33+J34-J35-J55 -> 6.3292422e+08
B38: Beginning equity | D38: =C42 -> 0 | E38: =D42 -> 502720325 | F38: =E42 -> 384531220 | G38: =F42 -> 353718300 | H38: =G42 -> 4.150357e+08 | I38: =H42 -> 4.8108856e+08 | J38: =I42 -> 5.5201979e+08
B39: Net income | D39: =D60 -> 149578348 | E39: =E60 -> 11742225 | F39: =F60 -> 39401076 | G39: =G60 -> 61317402 | H39: =H60 -> 66052855 | I39: =I60 -> 70931235 | J39: =J60 -> 74242200
B40: Dividends | D40: =D61*-1 -> -150000000 | E40: =E61*-1 -> 0 | F40: =F61*-1 -> 0 | G40: =G61*-1 -> 0 | H40: =H61*-1 -> 0 | I40: =I61*-1 -> 0 | J40: =J61*-1 -> -37121100
B41: Injection (Withdrawals) | D41: 150000000 | E41: -130000000 | F41: -70000000
B42: Ending equity | D42: =D85 -> 502720325 | E42: =E85 -> 384531220 | F42: =F85 -> 353718300 | G42: =SUM(G38:G41) -> 4.150357e+08 | H42: =SUM(H38:H41) -> 4.8108856e+08 | I42: =SUM(I38:I41) -> 5.5201979e+08 | J42: =SUM(J38:J41) -> 5.8914089e+08
A44: Net Debt and Interest Assumptions
B45: Short term borrowings interest rate | G45: 0.05 | H45: 0.05 | I45: 0.05 | J45: 0.05
B46: Long term debt interest rate | D46: =(D57)/(D79+D81) -> 0.042455292 | E46: =(E57)/(E79+E81) -> 0.032130913 | F46: =(F57)/(F79+F81) -> 0.070484199 | G46: 0.05 | H46: 0.05 | I46: 0.05 | J46: 0.05
A48: Income Statement | D48: 2022 | E48: 2023 | F48: 2024 | G48: 2025 | H48: 2026 | I48: 2027 | J48: 2028
B49: Revenue | D49: 921678907 | E49: 693278622 | F49: 1020003159 | G49: ='Recommended Loan '!E7 -> 1020003159 | H49: ='Recommended Loan '!F7 -> 1.0608033e+09 | I49: ='Recommended Loan '!G7 -> 1.1032354e+09 | J49: ='Recommended Loan '!H7 -> 1.1253001e+09
...

Sheet Recommended Loan   
A1: GULF PACKAGING INDUSTRIES LTD
A3: Revenue Assumptions
B4: ='Main Model'!D3 -> 2022A | C4: ='Main Model'!E3 -> 2023A | D4: ='Main Model'!F3 -> 2024A | E4: ='Main Model'!G3 -> 2025E | F4: ='Main Model'!H3 -> 2026E | G4: ='Main Model'!I3 -> 2027E | H4: ='Main Model'!J3 -> 2028E
A5: Local (SR) | B5: =B7-B6 -> 1.2903505e+08 | C5: =C7-C6 -> 2.1491637e+08 | D5: =D7-D6 -> 1.3260041e+08 | E5: =E7-E6 -> 1.5300047e+08 | F5: =F7-F6 -> 1.5912049e+08 | G5: =G7-G6 -> 1.6548531e+08 | H5: =H7-H6 -> 1.6879502e+08
A6: Export (SR) | B6: =B7*B10 -> 7.9264386e+08 | C6: =C7*C10 -> 4.7836225e+08 | D6: =D7*D10 -> 8.8740275e+08 | E6: =E10*E7 -> 8.6700269e+08 | F6: =F10*F7 -> 9.0168279e+08 | G6: =G10*G7 -> 9.377501e+08 | H6: =H10*H7 -> 9.5650511e+08
A7: Total Revenue (SR) | B7: ='Main Model'!D49 -> 921678907 | C7: ='Main Model'!E49 -> 693278622 | D7: ='Main Model'!F49 -> 1020003159 | E7: =(1+E8)*D7 -> 1020003159 | F7: =(1+F8)*E7 -> 1.0608033e+09 | G7: =(1+G8)*F7 -> 1.1032354e+09 | H7: =(1+H8)*G7 -> 1.1253001e+09
A8: Growth | B8: ='Main Model'!D9 -> 0.05 | C8: ='Main Model'!E9 -> -0.24780895 | D8: ='Main Model'!F9 -> 0.4712745 | E8: ='Main Model'!G9 -> 0 | F8: ='Main Model'!H9 -> 0.04 | G8: ='Main Model'!I9 -> 0.04 | H8: ='Main Model'!J9 -> 0.02
A10: Export Sales % | B10: 0.86 | C10: 0.69 | D10: 0.87 | E10: 0.85 | F10: 0.85 | G10: 0.85 | H10: 0.85
A12: COGS | B12: ='Main Model'!D50 -> 643105599 | C12: ='Main Model'!E50 -> 592508395 | D12: ='Main Model'!F50 -> 831546566 | E12: ='Main Model'!G50 -> 8.1600253e+08 | F12: ='Main Model'!H50 -> 8.4864263e+08 | G12: ='Main Model'!I50 -> 8.8258833e+08 | H12: ='Main Model'!J50 -> 9.002401e+08
A13: Less: Depreciation | B13: ='Main Model'!D54 -> 29486966 | C13: ='Main Model'!E54 -> 37674297 | D13: ='Main Model'!F54 -> 47946792 | E13: ='Main Model'!G54 -> 39422588 | F13: ='Main Model'!H54 -> 43449734 | G13: ='Main Model'!I54 -> 46808284 | H13: ='Main Model'!J54 -> 45542579
A14: Less: Amortization | B14: ='Main Model'!D55 -> 221799 | C14: ='Main Model'!E55 -> 869617 | D14: ='Main Model'!F55 -> 952414 | E14: ='Main Model'!G55 -> 952414 | F14: ='Main Model'!H55 -> 952414 | G14: ='Main Model'!I55 -> 952414 | H14: ='Main Model'!J55 -> 952414
A15: Cash COGS | B15: =B12-B13-B14 -> 613396834 | C15: =C12-C13-C14 -> 553964481 | D15: =D12-D13-D14 -> 782647360 | E15: =E12-E13-E14 -> 7.7562753e+08 | F15: =F12-F13-F14 -> 8.0424048e+08 | G15: =G12-G13-G14 -> 8.3482764e+08 | H15: =H12-H13-H14 -> 8.5374511e+08
A16: Local Cash COGS | B16: =B15*(1-B10) -> 85875557 | C16: =C15*(1-C10) -> 1.7172899e+08 | D16: =D15*(1-D10) -> 1.0174416e+08 | E16: =E15*(1-E10) -> 1.1634413e+08 | F16: =F15*(1-F10) -> 1.2063607e+08 | G16: =G15*(1-G10) -> 1.2522415e+08 | H16: =H15*(1-H10) -> 1.2806177e+08
B17: CCC
A18: Receivable days | B18: ='Main Model'!D163 -> 93.367882 | C18: ='Main Model'!E163 -> 109.49731 | D18: ='Main Model'!F163 -> 73.285285 | E18: ='Main Model'!G163 -> 73 | F18: ='Main Model'!H163 -> 73 | G18: ='Main Model'!I163 -> 73 | H18: ='Main Model'!J163 -> 73
A19: Inventory days | B19: ='Main Model'!D164 -> 55.186129 | C19: ='Main Model'!E164 -> 77.645546 | D19: ='Main Model'!F164 -> 68.027912 | E19: ='Main Model'!G164 -> 68 | F19: ='Main Model'!H164 -> 68 | G19: ='Main Model'!I164 -> 68 | H19: ='Main Model'!J164 -> 68
A20: Payable days | B20: ='Main Model'!D165 -> 21.031745 | C20: ='Main Model'!E165 -> 24.376041 | D20: ='Main Model'!F165 -> 20.657445 | E20: ='Main Model'!G165 -> 22 | F20: ='Main Model'!H165 -> 22 | G20: ='Main Model'!I165 -> 22 | H20: ='Main Model'!J165 -> 22 | J20: Local CCC
A21: Cash Conversion Cycle of total sales | B21: =B18+B19-B20 -> 127.52227 | C21: =C18+C19-C20 -> 162.76681 | D21: =D18+D19-D20 -> 120.65575 | E21: =E18+E19-E20 -> 119 | F21: =F18+F19-F20 -> 119 | G21: =G18+G19-G20 -> 119 | H21: =H18+H19-H20 -> 119 | K21: 2022A | L21: 2023A | M21: 2024A | N21: 2025E | O21: 2026E | P21: 2027E | Q21: 2028E
A22: local sales CCC | B22: 127.52227 | C22: 162.76681 | D22: 120.65575 | E22: 166 | F22: 166 | G22: 166 | H22: 166 | J22: Local Receivable days | K22: 93.367882 | L22: 109.49731 | M22: 73.285285 | N22: 120 | O22: 120 | P22: 120 | Q22: 120
J23: Local Inventory days | K23: 55.186129 | L23: 77.645546 | M23: 68.027912 | N23: 68 | O23: 68 | P23: 68 | Q23: 68
A24: Working Capital Need | B24: =B15*(B21/365) -> 2.1430618e+08 | C24: =C15*(C21/365) -> 2.4703297e+08 | D24: =D15*(D21/365) -> 2.5871481e+08 | E24: =E15*(E21/365) -> 2.5287582e+08 | F24: =F15*(F21/365) -> 2.6220443e+08 | G24: =G15*(G21/365) -> 2.7217668e+08 | H24: =H15*(H21/365) -> 2.783443e+08 | J24: Local Payable days | K24: 21.031745 | L24: 24.376041 | M24: 20.657445 | N24: 22 | O24: 22 | P24: 22 | Q24: 22
A25: Local working capital need based on over all company's CCC | B25: =B24*(1-B10) -> 30002865 | C25: =C24*(1-C10) -> 76580220 | D25: =D24*(1-D10) -> 33632926 | E25: =E24*(1-E10) -> 37931374 | F25: =F24*(1-F10) -> 39330665 | G25: =G24*(1-G10) -> 40826502 | H25: =H24*(1-H10) -> 41751644 | J25: Cash Conversion Cycle of total sales | K25: =K22+K23-K24 -> 127.52227 | L25: =L22+L23-L24 -> 162.76681 | M25: =M22+M23-M24 -> 120.65575 | N25: =N22+N23-N24 -> 166 | O25: =O22+O23-O24 -> 166 | P25: =P22+P23-P24 -> 166 | Q25: =Q22+Q23-Q24 -> 166
A27: Working Capital Need need based on local CCC | B27: =B15*(B22/365) -> 2.1430618e+08 | C27: =C15*(C22/365) -> 2.4703297e+08 | D27: =D15*(D22/365) -> 2.5871481e+08 | E27: =E15*(E22/365) -> 3.5275115e+08 | F27: =F15*(F22/365) -> 3.6576416e+08 | G27: =G15*(G22/365) -> 3.7967503e+08 | H27: =H15*(H22/365) -> 3.882786e+08
A28: Local working capital need based on local CCC | B28: =B27*(1-B10) -> 30002865 | C28: =C27*(1-C10) -> 76580220 | D28: =D27*(1-D10) -> 33632926 | E28: =E27*(1-E10) -> 52912672 | F28: =F27*(1-F10) -> 54864625 | G28: =G27*(1-G10) -> 56951255 | H28: =H27*(1-H10) -> 58241790
A29: Operating Cash Flow | B29: ='Main Model'!D104 -> 158190786 | C29: ='Main Model'!E104 -> 97870924 | D29: ='Main Model'!F104 -> 103464592 | E29: ='Main Model'!G104 -> 1.1004437e+08 | F29: ='Main Model'!H104 -> 1.0189481e+08 | G29: ='Main Model'!I104 -> 93271633 | H29: ='Main Model'!J104 -> 1.1547158e+08
A33: Repayment Date | B33: 2027
A34: Requested Amount | B34: 50000000
A35: Working Capital Need | B35: =ROUNDDOWN(F24,-5) -> 262200000
A36: Local Working Capital Need | B36: =ROUNDDOWN(F28,-5) -> 54800000
A37: Repayment capacity | B37: =ROUNDDOWN(G29+F29,-5) -> 195100000
A38: Stressed Repayment Capacity (30% discount) | B38: =B37*0.7 -> 136570000
A40: Recommended Loan for Approval "SR" | B40: =#REF! -> #REF! | C40: 50000000
B53: Recommended | C53: Not Recommended
