Workbook
Name \0: #REF!
Name \0: #REF!
Name \0: #REF!
Name \0: #REF!
Name \0: #REF!
Name \0: #REF!
Name \BASE_YEAR: #REF!
Name \BASE_YEAR: #REF!
Name \BASE_YEAR: #REF!
Name \BASE_YEAR: #REF!
Name \BASE_YEAR: #REF!
Name \BASE_YEAR: #REF!
Name \L: #REF!
Name \L: #REF!
Name \L: #REF!
Name \L: #REF!
Name \L: #REF!
Name \L: #REF!
Name \M: #REF!
Name \M: #REF!
Name \M: #REF!
Name \M: #REF!
Name \M: #REF!
Name \M: #REF!
Name \N: #REF!
Name \N: #REF!
Name \N: #REF!
Name \N: #REF!
Name \N: #REF!
Name \N: #REF!
Name \T: Assumptions!$AB$406:$AJ$414
Name \T: Assumptions!$AB$406:$AJ$414
Name \T: #REF!
Name \W: #REF!
Name \W: #REF!
Name \W: #REF!
Name \W: #REF!
Name \W: #REF!
Name \W: #REF!
Name _1_1: Assumptions!$A$5:$A$5
Name _1_1: Assumptions!$A$5:$A$5
Name _1_1: #REF!
Name _10_19: Assumptions!$A$382:$A$382
Name _10_19: Assumptions!$A$382:$A$382
Name _10_19: #REF!
Name _11_2: Assumptions!$A$91:$A$91
Name _11_2: Assumptions!$A$91:$A$91
Name _11_2: #REF!
Name _12_20: Assumptions!$A$403:$A$403
Name _12_20: Assumptions!$A$403:$A$403
Name _12_20: #REF!
Name _13_5: Assumptions!$A$134:$A$134
Name _13_5: Assumptions!$A$134:$A$134
Name _13_5: #REF!
Name _14_6: Assumptions!$A$162:$A$162
Name _14_6: Assumptions!$A$162:$A$162
Name _14_6: #REF!
Name _15_9: Assumptions!$A$196:$A$196
Name _15_9: Assumptions!$A$196:$A$196
Name _15_9: #REF!

Sheet BSL_AC
A1: Year | B1: =#REF! -> #REF! | C1: =#REF! -> #REF! | D1: =#REF! -> #REF! | E1: =#REF! -> #REF! | F1: =#REF! -> #REF! | G1: =#REF! -> #REF! | H1: =#REF! -> #REF! | I1: =#REF! -> #REF! | ... Q1: =#REF! -> #REF!
A2: Acpay | B2: =#REF!*1000 -> #REF! | C2: =#REF!*1000 -> #REF! | D2: =#REF!*1000 -> #REF! | E2: =#REF!*1000 -> #REF! | F2: =#REF!*1000 -> #REF! | G2: =#REF!*1000 -> #REF! | H2: =#REF!*1000 -> #REF! | I2: =#REF!*1000 -> #REF! | ... Q2: =#REF!*1000 -> #REF!
A3: Std | B3: =#REF!*1000 -> #REF! | C3: =#REF!*1000 -> #REF! | D3: =#REF!*1000 -> #REF! | E3: =#REF!*1000 -> #REF! | F3: =#REF!*1000 -> #REF! | G3: =#REF!*1000 -> #REF! | H3: =#REF!*1000 -> #REF! | I3: =#REF!*1000 -> #REF! | ... Q3: =#REF!*1000 -> #REF!
A4: Accruals | B4: =#REF!*1000 -> #REF! | C4: =#REF!*1000 -> #REF! | D4: =#REF!*1000 -> #REF! | E4: =#REF!*1000 -> #REF! | F4: =#REF!*1000 -> #REF! | G4: =#REF!*1000 -> #REF! | H4: =#REF!*1000 -> #REF! | I4: =#REF!*1000 -> #REF! | ... Q4: =#REF!*1000 -> #REF!
A5: Cplsidf | B5: =#REF!*1000 -> #REF! | C5: =#REF!*1000 -> #REF! | D5: =#REF!*1000 -> #REF! | E5: =#REF!*1000 -> #REF! | F5: =#REF!*1000 -> #REF! | G5: =#REF!*1000 -> #REF! | H5: =#REF!*1000 -> #REF! | I5: =#REF!*1000 -> #REF! | ... Q5: =#REF!*1000 -> #REF!
A6: Cplbank | B6: =#REF!*1000 -> #REF! | C6: =#REF!*1000 -> #REF! | D6: =#REF!*1000 -> #REF! | E6: =#REF!*1000 -> #REF! | F6: =#REF!*1000 -> #REF! | G6: =#REF!*1000 -> #REF! | H6: =#REF!*1000 -> #REF! | I6: =#REF!*1000 -> #REF! | ... Q6: =#REF!*1000 -> #REF!
A7: Cplother | B7: =#REF!*1000 -> #REF! | C7: =#REF!*1000 -> #REF! | D7: =#REF!*1000 -> #REF! | E7: =#REF!*1000 -> #REF! | F7: =#REF!*1000 -> #REF! | G7: =#REF!*1000 -> #REF! | H7: =#REF!*1000 -> #REF! | I7: =#REF!*1000 -> #REF! | ... Q7: =#REF!*1000 -> #REF!
A8: Other1 | B8: =#REF!*1000 -> #REF! | C8: =#REF!*1000 -> #REF! | D8: =#REF!*1000 -> #REF! | E8: =#REF!*1000 -> #REF! | F8: =#REF!*1000 -> #REF! | G8: =#REF!*1000 -> #REF! | H8: =#REF!*1000 -> #REF! | I8: =#REF!*1000 -> #REF! | ... Q8: =#REF!*1000 -> #REF!
A9: Other2 | B9: =#REF!*1000 -> #REF! | C9: =#REF!*1000 -> #REF! | D9: =#REF!*1000 -> #REF! | E9: =#REF!*1000 -> #REF! | F9: =#REF!*1000 -> #REF! | G9: =#REF!*1000 -> #REF! | H9: =#REF!*1000 -> #REF! | I9: =#REF!*1000 -> #REF! | ... Q9: =#REF!*1000 -> #REF!
A10: Currentliab | B10: =#REF!*1000 -> #REF! | C10: =#REF!*1000 -> #REF! | D10: =#REF!*1000 -> #REF! | E10: =#REF!*1000 -> #REF! | F10: =#REF!*1000 -> #REF! | G10: =#REF!*1000 -> #REF! | H10: =#REF!*1000 -> #REF! | I10: =#REF!*1000 -> #REF! | ... Q10: =#REF!*1000 -> #REF!
A11: Ltdsidf | B11: =#REF!*1000 -> #REF! | C11: =#REF!*1000 -> #REF! | D11: =#REF!*1000 -> #REF! | E11: =#REF!*1000 -> #REF! | F11: =#REF!*1000 -> #REF! | G11: =#REF!*1000 -> #REF! | H11: =#REF!*1000 -> #REF! | I11: =#REF!*1000 -> #REF! | ... Q11: =#REF!*1000 -> #REF!
A12: Ltdbank | B12: =#REF!*1000 -> #REF! | C12: =#REF!*1000 -> #REF! | D12: =#REF!*1000 -> #REF! | E12: =#REF!*1000 -> #REF! | F12: =#REF!*1000 -> #REF! | G12: =#REF!*1000 -> #REF! | H12: =#REF!*1000 -> #REF! | I12: =#REF!*1000 -> #REF! | ... Q12: =#REF!*1000 -> #REF!
A13: Ltdother | B13: =#REF!*1000 -> #REF! | C13: =#REF!*1000 -> #REF! | D13: =#REF!*1000 -> #REF! | E13: =#REF!*1000 -> #REF! | F13: =#REF!*1000 -> #REF! | G13: =#REF!*1000 -> #REF! | H13: =#REF!*1000 -> #REF! | I13: =#REF!*1000 -> #REF! | ... Q13: =#REF!*1000 -> #REF!
... A23: Totliabeq | B23: =#REF!*1000 -> #REF! | C23: =#REF!*1000 -> #REF! | D23: =#REF!*1000 -> #REF! | E23: =#REF!*1000 -> #REF! | F23: =#REF!*1000 -> #REF! | G23: =#REF!*1000 -> #REF! | H23: =#REF!*1000 -> #REF! | I23: =#REF!*1000 -> #REF! | ... Q23: =#REF!*1000 -> #REF!
A24: Months | B24: 12 | C24: 12 | D24: 12 | E24: 12 | F24: 12 | G24: 12 | H24: 12 | I24: 12 | J24: 12 | K24: 12 | L24: 12 | M24: 12 | N24: 12 | O24: 12 | P24: 12 | Q24: 12

Sheet BSA_AC
A1: Year | B1: =#REF! -> #REF! | C1: =#REF! -> #REF! | D1: =#REF! -> #REF! | E1: =#REF! -> #REF! | F1: =#REF! -> #REF! | G1: =#REF! -> #REF! | H1: =#REF! -> #REF! | I1: =#REF! -> #REF! | ... Q1: =#REF! -> #REF!
A2: Factorycash | B2: =#REF!*1000 -> #REF! | C2: =#REF!*1000 -> #REF! | D2: =#REF!*1000 -> #REF! | E2: =#REF!*1000 -> #REF! | F2: =#REF!*1000 -> #REF! | G2: =#REF!*1000 -> #REF! | H2: =#REF!*1000 -> #REF! | I2: =#REF!*1000 -> #REF! | ... Q2: =#REF!*1000 -> #REF!
A3: Accntsrec | B3: =#REF!*1000 -> #REF! | C3: =#REF!*1000 -> #REF! | D3: =#REF!*1000 -> #REF! | E3: =#REF!*1000 -> #REF! | F3: =#REF!*1000 -> #REF! | G3: =#REF!*1000 -> #REF! | H3: =#REF!*1000 -> #REF! | I3: =#REF!*1000 -> #REF! | ... Q3: =#REF!*1000 -> #REF!
A4: Inventory | B4: =#REF!*1000 -> #REF! | C4: =#REF!*1000 -> #REF! | D4: =#REF!*1000 -> #REF! | E4: =#REF!*1000 -> #REF! | F4: =#REF!*1000 -> #REF! | G4: =#REF!*1000 -> #REF! | H4: =#REF!*1000 -> #REF! | I4: =#REF!*1000 -> #REF! | ... Q4: =#REF!*1000 -> #REF!
A5: Lcmargins | B5: =#REF!*1000 -> #REF! | C5: =#REF!*1000 -> #REF! | D5: =#REF!*1000 -> #REF! | E5: =#REF!*1000 -> #REF! | F5: =#REF!*1000 -> #REF! | G5: =#REF!*1000 -> #REF! | H5: =#REF!*1000 -> #REF! | I5: =#REF!*1000 -> #REF! | ... Q5: =#REF!*1000 -> #REF!
A6: Prepaid | B6: =#REF!*1000 -> #REF! | C6: =#REF!*1000 -> #REF! | D6: =#REF!*1000 -> #REF! | E6: =#REF!*1000 -> #REF! | F6: =#REF!*1000 -> #REF! | G6: =#REF!*1000 -> #REF! | H6: =#REF!*1000 -> #REF! | I6: =#REF!*1000 -> #REF! | ... Q6: =#REF!*1000 -> #REF!
A7: Other1 | B7: =#REF!*1000 -> #REF! | C7: =#REF!*1000 -> #REF! | D7: =#REF!*1000 -> #REF! | E7: =#REF!*1000 -> #REF! | F7: =#REF!*1000 -> #REF! | G7: =#REF!*1000 -> #REF! | H7: =#REF!*1000 -> #REF! | I7: =#REF!*1000 -> #REF! | ... Q7: =#REF!*1000 -> #REF!
A8: Currentassets | B8: =#REF!*1000 -> #REF! | C8: =#REF!*1000 -> #REF! | D8: =#REF!*1000 -> #REF! | E8: =#REF!*1000 -> #REF! | F8: =#REF!*1000 -> #REF! | G8: =#REF!*1000 -> #REF! | H8: =#REF!*1000 -> #REF! | I8: =#REF!*1000 -> #REF! | ... Q8: =#REF!*1000 -> #REF!
A9: Land | B9: =#REF!*1000 -> #REF! | C9: =#REF!*1000 -> #REF! | D9: =#REF!*1000 -> #REF! | E9: =#REF!*1000 -> #REF! | F9: =#REF!*1000 -> #REF! | G9: =#REF!*1000 -> #REF! | H9: =#REF!*1000 -> #REF! | I9: =#REF!*1000 -> #REF! | ... Q9: =#REF!*1000 -> #REF!
A10: Buildings | B10: =#REF!*1000 -> #REF! | C10: =#REF!*1000 -> #REF! | D10: =#REF!*1000 -> #REF! | E10: =#REF!*1000 -> #REF! | F10: =#REF!*1000 -> #REF! | G10: =#REF!*1000 -> #REF! | H10: =#REF!*1000 -> #REF! | I10: =#REF!*1000 -> #REF! | ... Q10: =#REF!*1000 -> #REF!
A11: Machinery | B11: =#REF!*1000 -> #REF! | C11: =#REF!*1000 -> #REF! | D11: =#REF!*1000 -> #REF! | E11: =#REF!*1000 -> #REF! | F11: =#REF!*1000 -> #REF! | G11: =#REF!*1000 -> #REF! | H11: =#REF!*1000 -> #REF! | I11: =#REF!*1000 -> #REF! | ... Q11: =#REF!*1000 -> #REF!
A12: Furniture | B12: =#REF!*1000 -> #REF! | C12: =#REF!*1000 -> #REF! | D12: =#REF!*1000 -> #REF! | E12: =#REF!*1000 -> #REF! | F12: =#REF!*1000 -> #REF! | G12: =#REF!*1000 -> #REF! | H12: =#REF!*1000 -> #REF! | I12: =#REF!*1000 -> #REF! | ... Q12: =#REF!*1000 -> #REF!
A13: Vehicles | B13: =#REF!*1000 -> #REF! | C13: =#REF!*1000 -> #REF! | D13: =#REF!*1000 -> #REF! | E13: =#REF!*1000 -> #REF! | F13: =#REF!*1000 -> #REF! | G13: =#REF!*1000 -> #REF! | H13: =#REF!*1000 -> #REF! | I13: =#REF!*1000 -> #REF! | ... Q13: =#REF!*1000 -> #REF!
... A26: Totassets | B26: =#REF!*1000 -> #REF! | C26: =#REF!*1000 -> #REF! | D26: =#REF!*1000 -> #REF! | E26: =#REF!*1000 -> #REF! | F26: =#REF!*1000 -> #REF! | G26: =#REF!*1000 -> #REF! | H26: =#REF!*1000 -> #REF! | I26: =#REF!*1000 -> #REF! | ... Q26: =#REF!*1000 -> #REF!
A27: Months | B27: 12 | C27: 12 | D27: 12 | E27: 12 | F27: 12 | G27: 12 | H27: 12 | I27: 12 | J27: 12 | K27: 12 | L27: 12 | M27: 12 | N27: 12 | O27: 12 | P27: 12 | Q27: 12

Sheet IS_AC
A1: Year | B1: =#REF! -> #REF! | C1: =#REF! -> #REF! | D1: =#REF! -> #REF! | E1: =#REF! -> #REF! | F1: =#REF! -> #REF! | G1: =#REF! -> #REF! | H1: =#REF! -> #REF! | I1: =#REF! -> #REF! | ... Q1: =#REF! -> #REF!
A2: Sales | B2: =#REF!*1000 -> #REF! | C2: =#REF!*1000 -> #REF! | D2: =#REF!*1000 -> #REF! | E2: =#REF!*1000 -> #REF! | F2: =#REF!*1000 -> #REF! | G2: =#REF!*1000 -> #REF! | H2: =#REF!*1000 -> #REF! | I2: =#REF!*1000 -> #REF! | ... Q2: =#REF!*1000 -> #REF!
A3: Rawmat | B3: =#REF!*1000 -> #REF! | C3: =#REF!*1000 -> #REF! | D3: =#REF!*1000 -> #REF! | E3: =#REF!*1000 -> #REF! | F3: =#REF!*1000 -> #REF! | G3: =#REF!*1000 -> #REF! | H3: =#REF!*1000 -> #REF! | I3: =#REF!*1000 -> #REF! | ... Q3: =#REF!*1000 -> #REF!
A4: Dirlab | B4: =#REF!*1000 -> #REF! | C4: =#REF!*1000 -> #REF! | D4: =#REF!*1000 -> #REF! | E4: =#REF!*1000 -> #REF! | F4: =#REF!*1000 -> #REF! | G4: =#REF!*1000 -> #REF! | H4: =#REF!*1000 -> #REF! | I4: =#REF!*1000 -> #REF! | ... Q4: =#REF!*1000 -> #REF!
A5: Utils | B5: =#REF!*1000 -> #REF! | C5: =#REF!*1000 -> #REF! | D5: =#REF!*1000 -> #REF! | E5: =#REF!*1000 -> #REF! | F5: =#REF!*1000 -> #REF! | G5: =#REF!*1000 -> #REF! | H5: =#REF!*1000 -> #REF! | I5: =#REF!*1000 -> #REF! | ... Q5: =#REF!*1000 -> #REF!
A6: Maint | B6: =#REF!*1000 -> #REF! | C6: =#REF!*1000 -> #REF! | D6: =#REF!*1000 -> #REF! | E6: =#REF!*1000 -> #REF! | F6: =#REF!*1000 -> #REF! | G6: =#REF!*1000 -> #REF! | H6: =#REF!*1000 -> #REF! | I6: =#REF!*1000 -> #REF! | ... Q6: =#REF!*1000 -> #REF!
A7: Deprec | B7: =#REF!*1000 -> #REF! | C7: =#REF!*1000 -> #REF! | D7: =#REF!*1000 -> #REF! | E7: =#REF!*1000 -> #REF! | F7: =#REF!*1000 -> #REF! | G7: =#REF!*1000 -> #REF! | H7: =#REF!*1000 -> #REF! | I7: =#REF!*1000 -> #REF! | ... Q7: =#REF!*1000 -> #REF!
A8: Amort | B8: =#REF!*1000 -> #REF! | C8: =#REF!*1000 -> #REF! | D8: =#REF!*1000 -> #REF! | E8: =#REF!*1000 -> #REF! | F8: =#REF!*1000 -> #REF! | G8: =#REF!*1000 -> #REF! | H8: =#REF!*1000 -> #REF! | I8: =#REF!*1000 -> #REF! | ... Q8: =#REF!*1000 -> #REF!
A9: Othdirexp | B9: =#REF!*1000 -> #REF! | C9: =#REF!*1000 -> #REF! | D9: =#REF!*1000 -> #REF! | E9: =#REF!*1000 -> #REF! | F9: =#REF!*1000 -> #REF! | G9: =#REF!*1000 -> #REF! | H9: =#REF!*1000 -> #REF! | I9: =#REF!*1000 -> #REF! | ... Q9: =#REF!*1000 -> #REF!
A10: Cgs | B10: =#REF!*1000 -> #REF! | C10: =#REF!*1000 -> #REF! | D10: =#REF!*1000 -> #REF! | E10: =#REF!*1000 -> #REF! | F10: =#REF!*1000 -> #REF! | G10: =#REF!*1000 -> #REF! | H10: =#REF!*1000 -> #REF! | I10: =#REF!*1000 -> #REF! | ... Q10: =#REF!*1000 -> #REF!
A11: Grossmar | B11: =#REF!*1000 -> #REF! | C11: =#REF!*1000 -> #REF! | D11: =#REF!*1000 -> #REF! | E11: =#REF!*1000 -> #REF! | F11: =#REF!*1000 -> #REF! | G11: =#REF!*1000 -> #REF! | H11: =#REF!*1000 -> #REF! | I11: =#REF!*1000 -> #REF! | ... Q11: =#REF!*1000 -> #REF!
A12: Salesad | B12: =#REF!*1000 -> #REF! | C12: =#REF!*1000 -> #REF! | D12: =#REF!*1000 -> #REF! | E12: =#REF!*1000 -> #REF! | F12: =#REF!*1000 -> #REF! | G12: =#REF!*1000 -> #REF! | H12: =#REF!*1000 -> #REF! | I12: =#REF!*1000 -> #REF! | ... Q12: =#REF!*1000 -> #REF!
A13: Salar | B13: =#REF!*1000 -> #REF! | C13: =#REF!*1000 -> #REF! | D13: =#REF!*1000 -> #REF! | E13: =#REF!*1000 -> #REF! | F13: =#REF!*1000 -> #REF! | G13: =#REF!*1000 -> #REF! | H13: =#REF!*1000 -> #REF! | I13: =#REF!*1000 -> #REF! | ... Q13: =#REF!*1000 -> #REF!
... A22: Retear | B22: =#REF!*1000 -> #REF! | C22: =#REF!*1000 -> #REF! | D22: =#REF!*1000 -> #REF! | E22: =#REF!*1000 -> #REF! | F22: =#REF!*1000 -> #REF! | G22: =#REF!*1000 -> #REF! | H22: =#REF!*1000 -> #REF! | I22: =#REF!*1000 -> #REF! | ... Q22: =#REF!*1000 -> #REF!
A23: Months | B23: 12 | C23: 12 | D23: 12 | E23: 12 | F23: 12 | G23: 12 | H23: 12 | I23: 12 | J23: 12 | K23: 12 | L23: 12 | M23: 12 | N23: 12 | O23: 12 | P23: 12 | Q23: 12

Sheet FS
A1: FSYEAR | B1: =#REF! -> #REF! | C1: =#REF! -> #REF! | D1: =#REF! -> #REF! | E1: =#REF! -> #REF! | F1: =#REF! -> #REF! | G1: =#REF! -> #REF! | H1: =#REF! -> #REF! | I1: =#REF! -> #REF! | ... Q1: =#REF! -> #REF!
A2: =SUBSTITUTE(#REF!," ","") -> #REF! | B2: =#REF!*1000 -> #REF! | C2: =#REF! -> #REF! | D2: =#REF! -> #REF! | E2: =#REF! -> #REF! | F2: =#REF! -> #REF! | G2: =#REF! -> #REF! | H2: =#REF! -> #REF! | I2: =#REF! -> #REF! | J2: =#REF! -> #REF! | ... Q2: =#REF! -> #REF!
A3: =SUBSTITUTE(#REF!," ","") -> #REF! | B3: =#REF!*1000 -> #REF! | C3: =#REF! -> #REF! | D3: =#REF! -> #REF! | E3: =#REF! -> #REF! | F3: =#REF! -> #REF! | G3: =#REF! -> #REF! | H3: =#REF! -> #REF! | I3: =#REF! -> #REF! | J3: =#REF! -> #REF! | ... Q3: =#REF! -> #REF!
A4: =SUBSTITUTE(#REF!," ","") -> #REF! | B4: =#REF!*1000 -> #REF! | C4: =#REF! -> #REF! | D4: =#REF! -> #REF! | E4: =#REF! -> #REF! | F4: =#REF! -> #REF! | G4: =#REF! -> #REF! | H4: =#REF! -> #REF! | I4: =#REF! -> #REF! | J4: =#REF! -> #REF! | ... Q4: =#REF! -> #REF!
A5: =SUBSTITUTE(#REF!," ","") -> #REF! | B5: =#REF!*1000 -> #REF! | C5: =#REF! -> #REF! | D5: =#REF! -> #REF! | E5: =#REF! -> #REF! | F5: =#REF! -> #REF! | G5: =#REF! -> #REF! | H5: =#REF! -> #REF! | I5: =#REF! -> #REF! | J5: =#REF! -> #REF! | ... Q5: =#REF! -> #REF!
A6: =SUBSTITUTE(#REF!," ","") -> #REF! | B6: =#REF!*1000 -> #REF! | C6: =#REF! -> #REF! | D6: =#REF! -> #REF! | E6: =#REF! -> #REF! | F6: =#REF! -> #REF! | G6: =#REF! -> #REF! | H6: =#REF! -> #REF! | I6: =#REF! -> #REF! | J6: =#REF! -> #REF! | ... Q6: =#REF! -> #REF!
A7: =SUBSTITUTE(#REF!," ","") -> #REF! | B7: =#REF!*1000 -> #REF! | C7: =#REF! -> #REF! | D7: =#REF! -> #REF! | E7: =#REF! -> #REF! | F7: =#REF! -> #REF! | G7: =#REF! -> #REF! | H7: =#REF! -> #REF! | I7: =#REF! -> #REF! | J7: =#REF! -> #REF! | ... Q7: =#REF! -> #REF!
A8: =SUBSTITUTE(#REF!," ","") -> #REF! | B8: =#REF!*1000 -> #REF! | C8: =#REF! -> #REF! | D8: =#REF! -> #REF! | E8: =#REF! -> #REF! | F8: =#REF! -> #REF! | G8: =#REF! -> #REF! | H8: =#REF! -> #REF! | I8: =#REF! -> #REF! | J8: =#REF! -> #REF! | ... Q8: =#REF! -> #REF!
A9: =SUBSTITUTE(#REF!," ","") -> #REF! | B9: =#REF!*1000 -> #REF! | C9: =#REF! -> #REF! | D9: =#REF! -> #REF! | E9: =#REF! -> #REF! | F9: =#REF! -> #REF! | G9: =#REF! -> #REF! | H9: =#REF! -> #REF! | I9: =#REF! -> #REF! | J9: =#REF! -> #REF! | ... Q9: =#REF! -> #REF!
A10: =#REF! -> #REF! | B10: =#REF!*1000 -> #REF! | C10: =#REF! -> #REF! | D10: =#REF! -> #REF! | E10: =#REF! -> #REF! | F10: =#REF! -> #REF! | G10: =#REF! -> #REF! | H10: =#REF! -> #REF! | I10: =#REF! -> #REF! | J10: =#REF! -> #REF! | ... Q10: =#REF! -> #REF!
A11: =SUBSTITUTE(#REF!," ","") -> #REF! | B11: =#REF!*1000 -> #REF! | C11: =#REF! -> #REF! | D11: =#REF! -> #REF! | E11: =#REF! -> #REF! | F11: =#REF! -> #REF! | G11: =#REF! -> #REF! | H11: =#REF! -> #REF! | I11: =#REF! -> #REF! | J11: =#REF! -> #REF! | ... Q11: =#REF! -> #REF!
A12: =SUBSTITUTE(#REF!," ","") -> #REF! | B12: =#REF!*1000 -> #REF! | C12: =#REF! -> #REF! | D12: =#REF! -> #REF! | E12: =#REF! -> #REF! | F12: =#REF! -> #REF! | G12: =#REF! -> #REF! | H12: =#REF! -> #REF! | I12: =#REF! -> #REF! | J12: =#REF! -> #REF! | ... Q12: =#REF! -> #REF!
A13: =SUBSTITUTE(#REF!," ","") -> #REF! | B13: =#REF!*1000 -> #REF! | C13: =#REF! -> #REF! | D13: =#REF! -> #REF! | E13: =#REF! -> #REF! | F13: =#REF! -> #REF! | G13: =#REF! -> #REF! | H13: =#REF! -> #REF! | I13: =#REF! -> #REF! | J13: =#REF! -> #REF! | ... Q13: =#REF! -> #REF!
A14: =SUBSTITUTE(#REF!," ","") -> #REF! | B14: =#REF!*1000 -> #REF! | C14: =#REF! -> #REF! | D14: =#REF! -> #REF! | E14: =#REF! -> #REF! | F14: =#REF! -> #REF! | G14: =#REF! -> #REF! | H14: =#REF! -> #REF! | I14: =#REF! -> #REF! | J14: =#REF! -> #REF! | ... Q14: =#REF! -> #REF!
A15: =#REF! -> #REF! | B15: =#REF!*1000 -> #REF! | C15: =#REF! -> #REF! | D15: =#REF! -> #REF! | E15: =#REF! -> #REF! | F15: =#REF! -> #REF! | G15: =#REF! -> #REF! | H15: =#REF! -> #REF! | I15: =#REF! -> #REF! | J15: =#REF! -> #REF! | ... Q15: =#REF! -> #REF!
A16: =SUBSTITUTE(#REF!," ","") -> #REF! | B16: =#REF! -> #REF! | C16: =#REF! -> #REF! | D16: =#REF! -> #REF! | E16: =#REF! -> #REF! | F16: =#REF! -> #REF! | G16: =#REF! -> #REF! | H16: =#REF! -> #REF! | I16: =#REF! -> #REF! | ... R16: =#REF! -> #REF!
A17: =SUBSTITUTE(#REF!," ","") -> #REF! | B17: =#REF! -> #REF! | C17: =#REF! -> #REF! | D17: =#REF! -> #REF! | E17: =#REF! -> #REF! | F17: =#REF! -> #REF! | G17: =#REF! -> #REF! | H17: =#REF! -> #REF! | I17: =#REF! -> #REF! | ... Q17: =#REF! -> #REF!
A18: =SUBSTITUTE(#REF!," ","") -> #REF! | B18: =#REF! -> #REF! | C18: =#REF! -> #REF! | D18: =#REF! -> #REF! | E18: =#REF! -> #REF! | F18: =#REF! -> #REF! | G18: =#REF! -> #REF! | H18: =#REF! -> #REF! | I18: =#REF! -> #REF! | ... Q18: =#REF! -> #REF!
A19: =SUBSTITUTE(#REF!," ","") -> #REF! | B19: =#REF! -> #REF! | C19: =#REF! -> #REF! | D19: =#REF! -> #REF! | E19: =#REF! -> #REF! | F19: =#REF! -> #REF! | G19: =#REF! -> #REF! | H19: =#REF! -> #REF! | I19: =#REF! -> #REF! | ... Q19: =#REF! -> #REF!
A20: =SUBSTITUTE(#REF!," ","") -> #REF! | B20: =#REF! -> #REF! | C20: =#REF! -> #REF! | D20: =#REF! -> #REF! | E20: =#REF! -> #REF! | F20: =#REF! -> #REF! | G20: =#REF! -> #REF! | H20: =#REF! -> #REF! | I20: =#REF! -> #REF! | ... Q20: =#REF! -> #REF!
A21: =SUBSTITUTE(#REF!," ","") -> #REF! | B21: =#REF! -> #REF! | C21: =#REF! -> #REF! | D21: =#REF! -> #REF! | E21: =#REF! -> #REF! | F21: =#REF! -> #REF! | G21: =#REF! -> #REF! | H21: =#REF! -> #REF! | I21: =#REF! -> #REF! | ... Q21: =#REF! -> #REF!

Sheet GAV
A1: =#REF! -> #REF!
A2: =#REF! -> #REF!

Sheet Assumptions
J1: FORECAST ASSUMPTIONS | P1: Attachment C-1
A5: 1. | B5: Sales Assumptions: The following tables set out the selling price per product, raw material cost per product and quantities of the various product lines to be sold in each of the forecast years. It further show the contributin per product (percentage o
B6: margine left after deducting the RM cost from the selling price).
C8: Product Line | D8: Unit | E8: SR | G8: Contribution | H8: ='Financial Stat.'!C318 -> 2026 | I8: =""&'Financial Stat.'!D318 -> 2027 | J8: =""&'Financial Stat.'!E318 -> 2028 | K8: =""&'Financial Stat.'!F318 -> 2029 | L8: =""&'Financial Stat.'!G318 -> 2030 | M8: =""&'Financial Stat.'!H318 -> 2031 | N8: =""&'Financial Stat.'!I318 -> 2032 | O8: =""&'Financial Stat.'!J318 -> 2033 | P8: =""&'Financial Stat.'!K318 -> 2034 | ... V8: =""&'Financial Stat.'!Q318 -> 2040 | X8: =""&'Financial Stat.'!S318 -> 2042 | Y8: =""&'Financial Stat.'!T318 -> 2043
D9: Type | E9: Selling Price | F9: RM Cost | G9: Per Product | H9: Volume | I9: Volume | J9: Volume | K9: Volume | L9: Volume | M9: Volume | N9: Volume | O9: Volume | P9: Volume | Q9: Volume | R9: Volume | S9: Volume | T9: Volume | U9: Volume | V9: Volume | X9: Volume | Y9: Volume
G10: =IF(E10=0," ",1-(F10/E10))
C11: PET Cups Local | E11: =8190*0.8 -> 6552 | F11: =3648 -> 3648 | G11: =IF(E11=0," ",1-(F11/E11)) -> 0.44322344 | H11: 625 | I11: 800 | J11: 1050 | K11: 1400 | L11: 1800 | M11: 1800 | N11: 1800 | O11: 1800 | P11: 1800 | Q11: 1800 | R11: 1800 | S11: 1800 | T11: 1800 | U11: 1800 | V11: 1800
C12: PET Cups (Export) | E12: =8190*0.8 -> 6552 | F12: =3648 -> 3648 | G12: =IF(E12=0," ",1-(F12/E12)) -> 0.44322344 | H12: 75 | I12: 100 | J12: 150 | K12: 200 | L12: 300 | M12: 300 | N12: 300 | O12: 300 | P12: 300 | Q12: 300 | R12: 300 | S12: 300 | T12: 300 | U12: 300 | V12: 300
C13: PP Containers Local | E13: =9178*0.8 -> 7342.4 | F13: =3497 -> 3497 | G13: =IF(E13=0," ",1-(F13/E13)) -> 0.52372521 | H13: 1440 | I13: 1530 | J13: 1575 | K13: 1600 | L13: 1650 | M13: 1650 | N13: 1650 | O13: 1650 | P13: 1650 | Q13: 1650 | R13: 1650 | S13: 1650 | T13: 1650 | U13: 1650 | V13: 1650
C14: PP Containers (Export) | E14: =8911*0.8 -> 7128.8 | F14: =3497 -> 3497 | G14: =IF(E14=0," ",1-(F14/E14)) -> 0.50945461 | H14: 195 | I14: 205 | J14: 215 | K14: 225 | L14: 230 | M14: 230 | N14: 230 | O14: 230 | P14: 230 | Q14: 230 | R14: 230 | S14: 230 | T14: 230 | U14: 230 | V14: 230
C15: PET Containers Local | E15: =6256*0.8 -> 5004.8 | F15: =3648 -> 3648 | G15: =IF(E15=0," ",1-(F15/E15)) -> 0.27109974 | H15: 285 | I15: 300 | J15: 330 | K15: 350 | L15: 365 | M15: 365 | N15: 365 | O15: 365 | P15: 365 | Q15: 365 | R15: 365 | S15: 365 | T15: 365 | U15: 365 | V15: 365
C16: PET Containers (Export) | E16: =6764*0.8 -> 5411.2 | F16: =3648 -> 3648 | G16: =IF(E16=0," ",1-(F16/E16)) -> 0.3258427 | H16: 45 | I16: 50 | J16: 55 | K16: 60 | L16: 70 | M16: 70 | N16: 70 | O16: 70 | P16: 70 | Q16: 70 | R16: 70 | S16: 70 | T16: 70 | U16: 70 | V16: 70
G17: =IF(E17=0," ",1-(F17/E17))
G18: =IF(E18=0," ",1-(F18/E18))
G19: =IF(E19=0," ",1-(F19/E19))
G20: =IF(E20=0," ",1-(F20/E20))
G21: =IF(E21=0," ",1-(F21/E21))
G22: =IF(E22=0," ",1-(F22/E22))
G23: =IF(E23=0," ",1-(F23/E23))
G24: =IF(E24=0," ",1-(F24/E24))
G25: =IF(E25=0," ",1-(F25/E25))
G26: =IF(E26=0," ",1-(F26/E26))
G27: =IF(E27=0," ",1-(F27/E27))
G28: =IF(E28=0," ",1-(F28/E28))
... G41: =IF(E41=0," ",1-(F41/E41))
D42: Total Units | H42: =SUM(H11:H40) -> 2665 | I42: =SUM(I11:I40) -> 2985 | J42: =SUM(J11:J40) -> 3375 | K42: =SUM(K11:K40) -> 3835 | L42: =SUM(L11:L40) -> 4415 | M42: =SUM(M11:M40) -> 4415 | N42: =SUM(N11:N40) -> 4415 | O42: =SUM(O11:O40) -> 4415 | ... V42: =SUM(V11:V40) -> 4415
A49: 2 | B49: Revenues Per Products: (SR'000) | L49: Attachment C-2
C52: Product Line | D52: =" "&'Financial Stat.'!C318 -> 2026 | E52: =" "&'Financial Stat.'!D318 -> 2027 | F52: =" "&'Financial Stat.'!E318 -> 2028 | G52: =" "&'Financial Stat.'!F318 -> 2029 | H52: =" "&'Financial Stat.'!G318 -> 2030 | I52: =" "&'Financial Stat.'!H318 -> 2031 | J52: =" "&'Financial Stat.'!I318 -> 2032 | K52: =" "&'Financial Stat.'!J318 -> 2033 | ... R52: =" "&'Financial Stat.'!Q318 -> 2040
D53: Revnue | E53: Revnue | F53: Revnue | G53: Revnue | H53: Revnue | I53: Revnue | J53: Revnue | K53: Revnue | L53: Revnue | M53: Revnue | N53: Revnue | O53: Revnue | P53: Revnue | Q53: Revnue | R53: Revnue
B55: =B11 -> 0 | C55: =IF(ISERR(TRIM(C11)),"",TRIM(C11)) -> PET Cups Local | D55: =ROUND((+H11*$E11)/1000,0) -> 4095 | E55: =ROUND((+I11*$E11)/1000,0) -> 5242 | F55: =ROUND((+J11*$E11)/1000,0) -> 6880 | G55: =ROUND((+K11*$E11)/1000,0) -> 9173 | H55: =ROUND((+L11*$E11)/1000,0) -> 11794 | I55: =ROUND((+M11*$E11)/1000,0) -> 11794 | J55: =ROUND((+N11*$E11)/1000,0) -> 11794 | K55: =ROUND((+O11*$E11)/1000,0) -> 11794 | ... R55: =ROUND((+V11*$E11)/1000,0) -> 11794
B56: =B12 -> 0 | C56: =IF(ISERR(TRIM(C12)),"",TRIM(C12)) -> PET Cups (Export) | D56: =ROUND((+H12*$E12)/1000,0) -> 491 | E56: =ROUND((+I12*$E12)/1000,0) -> 655 | F56: =ROUND((+J12*$E12)/1000,0) -> 983 | G56: =ROUND((+K12*$E12)/1000,0) -> 1310 | H56: =ROUND((+L12*$E12)/1000,0) -> 1966 | I56: =ROUND((+M12*$E12)/1000,0) -> 1966 | J56: =ROUND((+N12*$E12)/1000,0) -> 1966 | K56: =ROUND((+O12*$E12)/1000,0) -> 1966 | ... R56: =ROUND((+V12*$E12)/1000,0) -> 1966
B57: =B13 -> 0 | C57: =IF(ISERR(TRIM(C13)),"",TRIM(C13)) -> PP Containers Local | D57: =ROUND((+H13*$E13)/1000,0) -> 10573 | E57: =ROUND((+I13*$E13)/1000,0) -> 11234 | F57: =ROUND((+J13*$E13)/1000,0) -> 11564 | G57: =ROUND((+K13*$E13)/1000,0) -> 11748 | H57: =ROUND((+L13*$E13)/1000,0) -> 12115 | I57: =ROUND((+M13*$E13)/1000,0) -> 12115 | J57: =ROUND((+N13*$E13)/1000,0) -> 12115 | K57: =ROUND((+O13*$E13)/1000,0) -> 12115 | ... R57: =ROUND((+V13*$E13)/1000,0) -> 12115
B58: =B14 -> 0 | C58: =IF(ISERR(TRIM(C14)),"",TRIM(C14)) -> PP Containers (Export) | D58: =ROUND((+H14*$E14)/1000,0) -> 1390 | E58: =ROUND((+I14*$E14)/1000,0) -> 1461 | F58: =ROUND((+J14*$E14)/1000,0) -> 1533 | G58: =ROUND((+K14*$E14)/1000,0) -> 1604 | H58: =ROUND((+L14*$E14)/1000,0) -> 1640 | I58: =ROUND((+M14*$E14)/1000,0) -> 1640 | J58: =ROUND((+N14*$E14)/1000,0) -> 1640 | K58: =ROUND((+O14*$E14)/1000,0) -> 1640 | ... R58: =ROUND((+V14*$E14)/1000,0) -> 1640
B59: =B15 -> 0 | C59: =IF(ISERR(TRIM(C15)),"",TRIM(C15)) -> PET Containers Local | D59: =ROUND((+H15*$E15)/1000,0) -> 1426 | E59: =ROUND((+I15*$E15)/1000,0) -> 1501 | F59: =ROUND((+J15*$E15)/1000,0) -> 1652 | G59: =ROUND((+K15*$E15)/1000,0) -> 1752 | H59: =ROUND((+L15*$E15)/1000,0) -> 1827 | I59: =ROUND((+M15*$E15)/1000,0) -> 1827 | J59: =ROUND((+N15*$E15)/1000,0) -> 1827 | K59: =ROUND((+O15*$E15)/1000,0) -> 1827 | ... R59: =ROUND((+V15*$E15)/1000,0) -> 1827
B60: =B16 -> 0 | C60: =IF(ISERR(TRIM(C16)),"",TRIM(C16)) -> PET Containers (Export) | D60: =ROUND((+H16*$E16)/1000,0) -> 244 | E60: =ROUND((+I16*$E16)/1000,0) -> 271 | F60: =ROUND((+J16*$E16)/1000,0) -> 298 | G60: =ROUND((+K16*$E16)/1000,0) -> 325 | H60: =ROUND((+L16*$E16)/1000,0) -> 379 | I60: =ROUND((+M16*$E16)/1000,0) -> 379 | J60: =ROUND((+N16*$E16)/1000,0) -> 379 | K60: =ROUND((+O16*$E16)/1000,0) -> 379 | ... R60: =ROUND((+V16*$E16)/1000,0) -> 379
B61: =B17 -> 0 | C61: =IF(ISERR(TRIM(C17)),"",TRIM(C17)) | D61: =ROUND((+H17*$E17)/1000,0) -> 0 | E61: =ROUND((+I17*$E17)/1000,0) -> 0 | F61: =ROUND((+J17*$E17)/1000,0) -> 0 | G61: =ROUND((+K17*$E17)/1000,0) -> 0 | H61: =ROUND((+L17*$E17)/1000,0) -> 0 | I61: =ROUND((+M17*$E17)/1000,0) -> 0 | J61: =ROUND((+N17*$E17)/1000,0) -> 0 | K61: =ROUND((+O17*$E17)/1000,0) -> 0 | ... R61: =ROUND((+V17*$E17)/1000,0) -> 0
B62: =B18 -> 0 | C62: =IF(ISERR(TRIM(C18)),"",TRIM(C18)) | D62: =ROUND((+H18*$E18)/1000,0) -> 0 | E62: =ROUND((+I18*$E18)/1000,0) -> 0 | F62: =ROUND((+J18*$E18)/1000,0) -> 0 | G62: =ROUND((+K18*$E18)/1000,0) -> 0 | H62: =ROUND((+L18*$E18)/1000,0) -> 0 | I62: =ROUND((+M18*$E18)/1000,0) -> 0 | J62: =ROUND((+N18*$E18)/1000,0) -> 0 | K62: =ROUND((+O18*$E18)/1000,0) -> 0 | ... R62: =ROUND((+V18*$E18)/1000,0) -> 0
B63: =B19 -> 0 | C63: =IF(ISERR(TRIM(C19)),"",TRIM(C19)) | D63: =ROUND((+H19*$E19)/1000,0) -> 0 | E63: =ROUND((+I19*$E19)/1000,0) -> 0 | F63: =ROUND((+J19*$E19)/1000,0) -> 0 | G63: =ROUND((+K19*$E19)/1000,0) -> 0 | H63: =ROUND((+L19*$E19)/1000,0) -> 0 | I63: =ROUND((+M19*$E19)/1000,0) -> 0 | J63: =ROUND((+N19*$E19)/1000,0) -> 0 | K63: =ROUND((+O19*$E19)/1000,0) -> 0 | ... R63: =ROUND((+V19*$E19)/1000,0) -> 0
B64: =B20 -> 0 | C64: =IF(ISERR(TRIM(C20)),"",TRIM(C20)) | D64: =ROUND((+H20*$E20)/1000,0) -> 0 | E64: =ROUND((+I20*$E20)/1000,0) -> 0 | F64: =ROUND((+J20*$E20)/1000,0) -> 0 | G64: =ROUND((+K20*$E20)/1000,0) -> 0 | H64: =ROUND((+L20*$E20)/1000,0) -> 0 | I64: =ROUND((+M20*$E20)/1000,0) -> 0 | J64: =ROUND((+N20*$E20)/1000,0) -> 0 | K64: =ROUND((+O20*$E20)/1000,0) -> 0 | ... R64: =ROUND((+V20*$E20)/1000,0) -> 0
B65: =B21 -> 0 | C65: =IF(ISERR(TRIM(C21)),"",TRIM(C21)) | D65: =ROUND((+H21*$E21)/1000,0) -> 0 | E65: =ROUND((+I21*$E21)/1000,0) -> 0 | F65: =ROUND((+J21*$E21)/1000,0) -> 0 | G65: =ROUND((+K21*$E21)/1000,0) -> 0 | H65: =ROUND((+L21*$E21)/1000,0) -> 0 | I65: =ROUND((+M21*$E21)/1000,0) -> 0 | J65: =ROUND((+N21*$E21)/1000,0) -> 0 | K65: =ROUND((+O21*$E21)/1000,0) -> 0 | ... R65: =ROUND((+V21*$E21)/1000,0) -> 0
...

Sheet Financial Stat.
K1: Income Statement | P1: Attachment B-1
R4: (SR in 000s)
C5: HISTORICAL | G5: PROJECTIONS
B6: =IF(H_1=0," ",H_1) | C6: =IF(H_2=0," ",H_2) | D6: =IF(H_3=0," ",H_3) | E6: =IF(H_4=0," ",H_4) | F6: =IF(H_5=0," ",H_5) | G6: =B318 -> 2025 | H6: =C318 -> 2026 | I6: =D318 -> 2027 | J6: =E318 -> 2028 | K6: =F318 -> 2029 | L6: =G318 -> 2030 | M6: =H318 -> 2031 | N6: =I318 -> 2032 | ... V6: =Q318 -> 2040
A8: Sales | G8: 19700 | H8: =Assumptions!D86 -> 18219 | I8: =Assumptions!E86 -> 20364 | J8: =Assumptions!F86 -> 22910 | K8: =Assumptions!G86 -> 25912 | L8: =Assumptions!H86 -> 29721 | M8: =Assumptions!I86 -> 29721 | N8: =Assumptions!J86 -> 29721 | O8: =Assumptions!K86 -> 29721 | ... V8: =Assumptions!R86 -> 29721
A10: Cost of Goods Sold:
A11: Raw Materials | G11: 8136 | H11: =Assumptions!D129 -> 9476 | I11: =Assumptions!E129 -> 10626 | J11: =Assumptions!F129 -> 12042 | K11: =Assumptions!G129 -> 13715 | L11: =Assumptions!H129 -> 15821 | M11: =Assumptions!I129 -> 15821 | N11: =Assumptions!J129 -> 15821 | O11: =Assumptions!K129 -> 15821 | ... V11: =Assumptions!R129 -> 15821
A12: Labour | G12: 2233 | H12: =Assumptions!F189 -> 2233 | I12: =Assumptions!G189 -> 2233 | J12: =Assumptions!H189 -> 2233 | K12: =Assumptions!I189 -> 2233 | L12: =Assumptions!J189 -> 2233 | M12: =Assumptions!K189 -> 2233 | N12: =Assumptions!L189 -> 2233 | O12: =Assumptions!M189 -> 2233 | ... V12: =Assumptions!T189 -> 2233
A13: Utilities | G13: 990 | H13: =ROUND(Assumptions!E211,0) -> 1150 | I13: =ROUND(Assumptions!F211,0) -> 1288 | J13: =ROUND(Assumptions!G211,0) -> 1456 | K13: =ROUND(Assumptions!H211,0) -> 1655 | L13: =ROUND(Assumptions!I211,0) -> 1905 | M13: =ROUND(Assumptions!J211,0) -> 1905 | N13: =ROUND(Assumptions!K211,0) -> 1905 | O13: =ROUND(Assumptions!L211,0) -> 1905 | ... V13: =ROUND(Assumptions!S211,0) -> 1905
A14: Maintenance | G14: =Assumptions!G341 -> 0 | H14: =ROUND(Assumptions!E227*G60+Assumptions!E228*G61+Assumptions!E229*G62+Assumptions!E230*G63+Assumptions!E231*G64+Assumptions!E232*G65+Assumptions!E233*G66,0) -> 610 | I14: =ROUND(Assumptions!E227*H60+Assumptions!E228*H61+Assumptions!E229*H62+Assumptions!E230*H63+Assumptions!E231*H64+Assumptions!E232*H65+Assumptions!E233*H66,0) -> 610 | J14: =ROUND(Assumptions!E227*I60+Assumptions!E228*I61+Assumptions!E229*I62+Assumptions!E230*I63+Assumptions!E231*I64+Assumptions!E232*I65+Assumptions!E233*I66,0) -> 610 | K14: =ROUND(Assumptions!E227*J60+Assumptions!E228*J61+Assumptions!E229*J62+Assumptions!E230*J63+Assumptions!E231*J64+Assumptions!E232*J65+Assumptions!E233*J66,0) -> 610 | L14: =ROUND(Assumptions!E227*K60+Assumptions!E228*K61+Assumptions!E229*K62+Assumptions!E230*K63+Assumptions!E231*K64+Assumptions!E232*K65+Assumptions!E233*K66,0) -> 610 | M14: =ROUND(Assumptions!E227*L60+Assumptions!E228*L61+Assumptions!E229*L62+Assumptions!E230*L63+Assumptions!E231*L64+Assumptions!E232*L65+Assumptions!E233*L66,0) -> 610 | N14: =ROUND(Assumptions!E227*M60+Assumptions!E228*M61+Assumptions!E229*M62+Assumptions!E230*M63+Assumptions!E231*M64+Assumptions!E232*M65+Assumptions!E233*M66,0) -> 610 | O14: =ROUND(Assumptions!E227*N60+Assumptions!E228*N61+Assumptions!E229*N62+Assumptions!E230*N63+Assumptions!E231*N64+Assumptions!E232*N65+Assumptions!E233*N66,0) -> 610 | P14: =ROUND(Assumptions!E227*O60+Assumptions!E228*O61+Assumptions!E229*O62+Assumptions!E230*O63+Assumptions!E231*O64+Assumptions!E232*O65+Assumptions!E233*O66,0) -> 610 | Q14: =ROUND(Assumptions!E227*P60+Assumptions!E228*P61+Assumptions!E229*P62+Assumptions!E230*P63+Assumptions!E231*P64+Assumptions!E232*P65+Assumptions!E233*P66,0) -> 610 | R14: =ROUND(Assumptions!E227*Q60+Assumptions!E228*Q61+Assumptions!E229*Q62+Assumptions!E230*Q63+Assumptions!E231*Q64+Assumptions!E232*Q65+Assumptions!E233*Q66,0) -> 610 | S14: =ROUND(Assumptions!E227*R60+Assumptions!E228*R61+Assumptions!E229*R62+Assumptions!E230*R63+Assumptions!E231*R64+Assumptions!E232*R65+Assumptions!E233*R66,0) -> 610 | T14: =ROUND(Assumptions!E227*S60+Assumptions!E228*S61+Assumptions!E229*S62+Assumptions!E230*S63+Assumptions!E231*S64+Assumptions!E232*S65+Assumptions!E233*S66,0) -> 610 | U14: =ROUND(Assumptions!E227*T60+Assumptions!E228*T61+Assumptions!E229*T62+Assumptions!E230*T63+Assumptions!E231*T64+Assumptions!E232*T65+Assumptions!E233*T66,0) -> 610 | V14: =ROUND(Assumptions!E227*U60+Assumptions!E228*U61+Assumptions!E229*U62+Assumptions!E230*U63+Assumptions!E231*U64+Assumptions!E232*U65+Assumptions!E233*U66,0) -> 610
A15: Depreciation | G15: =Assumptions!F252 -> 0 | H15: =Assumptions!G252 -> 702 | I15: =Assumptions!H252 -> 702 | J15: =Assumptions!I252 -> 702 | K15: =Assumptions!J252 -> 702 | L15: =Assumptions!K252 -> 702 | M15: =Assumptions!L252 -> 630 | N15: =Assumptions!M252 -> 630 | ... V15: =Assumptions!U252 -> 630
A16: Amortization | G16: =610+702 -> 1312 | H16: =Assumptions!G255 -> 399 | I16: =Assumptions!H255 -> 0 | J16: =Assumptions!I255 -> 0 | K16: =Assumptions!J255 -> 0 | L16: =Assumptions!K255 -> 0 | M16: =Assumptions!L255 -> 0 | N16: =Assumptions!M255 -> 0 | O16: =Assumptions!N255 -> 0 | ... V16: =Assumptions!U255 -> 0
A17: other
A18: Other | B18: 0 | C18: 0 | D18: 0 | E18: 0 | F18: 0 | G18: 0 | H18: 0 | I18: 0 | J18: 0 | K18: 0 | L18: 0 | M18: 0 | N18: 0 | O18: 0 | P18: 0 | Q18: 0 | R18: 0 | S18: 0 | T18: 0 | U18: 0 | V18: 0
A20: Total of CGS | B20: =ROUND(SUM(B10:B18),0) -> 0 | C20: =ROUND(SUM(C10:C18),0) -> 0 | D20: =ROUND(SUM(D10:D18),0) -> 0 | E20: =ROUND(SUM(E10:E18),0) -> 0 | F20: =ROUND(SUM(F10:F18),0) -> 0 | G20: =ROUND(SUM(G10:G18),0) -> 12671 | H20: =ROUND(SUM(H10:H18),0) -> 14570 | I20: =ROUND(SUM(I10:I18),0) -> 15459 | ... V20: =ROUND(SUM(V10:V18),0) -> 21199
A22: Gross Margin | B22: =B8-B20 -> 0 | C22: =C8-C20 -> 0 | D22: =D8-D20 -> 0 | E22: =E8-E20 -> 0 | F22: =F8-F20 -> 0 | G22: =G8-G20 -> 7029 | H22: =H8-H20 -> 3649 | I22: =I8-I20 -> 4905 | ... V22: =V8-V20 -> 8522
A24: Indirect Costs:
A25: Sales, Gen. & Admin. | G25: =H25 -> 1912.995 | H25: =IF(H8*Assumptions!E268<Assumptions!E267,Assumptions!E267,H8*Assumptions!E268) -> 1912.995 | I25: =IF(I8*Assumptions!F268<Assumptions!F267,Assumptions!F267,I8*Assumptions!F268) -> 2443.68 | J25: =IF(J8*Assumptions!G268<Assumptions!G267,Assumptions!G267,J8*Assumptions!G268) -> 2978.3 | K25: =IF(K8*Assumptions!H268<Assumptions!H267,Assumptions!H267,K8*Assumptions!H268) -> 3627.68 | L25: =IF(L8*Assumptions!I268<Assumptions!I267,Assumptions!I267,L8*Assumptions!I268) -> 4160.94 | M25: =IF(M8*Assumptions!I268<Assumptions!I267,Assumptions!I267,M8*Assumptions!I268) -> 4160.94 | N25: =IF(N8*Assumptions!I268<Assumptions!I267,Assumptions!I267,N8*Assumptions!I268) -> 4160.94 | O25: =IF(O8*Assumptions!I268<Assumptions!I267,Assumptions!I267,O8*Assumptions!I268) -> 4160.94 | P25: =IF(P8*Assumptions!I268<Assumptions!I267,Assumptions!I267,P8*Assumptions!I268) -> 4160.94 | Q25: =IF(Q8*Assumptions!I268<Assumptions!I267,Assumptions!I267,Q8*Assumptions!I268) -> 4160.94 | R25: =IF(R8*Assumptions!N268<Assumptions!N267,Assumptions!N267,R8*Assumptions!N268) -> 4160.94 | S25: =IF(S8*Assumptions!N268<Assumptions!N267,Assumptions!N267,S8*Assumptions!N268) -> 4160.94 | T25: =IF(T8*Assumptions!N268<Assumptions!N267,Assumptions!N267,T8*Assumptions!N268) -> 4160.94 | U25: =IF(U8*Assumptions!N268<Assumptions!N267,Assumptions!N267,U8*Assumptions!N268) -> 4160.94 | V25: =IF(V8*Assumptions!N268<Assumptions!N267,Assumptions!N267,V8*Assumptions!N268) -> 4160.94
A26: Salaries | G26: =F26 -> 0 | H26: =Assumptions!F162 -> 0 | I26: =Assumptions!G162 -> 0 | J26: =Assumptions!H162 -> 0 | K26: =Assumptions!I162 -> 0 | L26: =Assumptions!J162 -> 0 | M26: =Assumptions!K162 -> 0 | N26: =Assumptions!L162 -> 0 | O26: =Assumptions!M162 -> 0 | ... V26: =Assumptions!T162 -> 0
A27: Finance Charges | G27: =ROUND(Assumptions!E280*(F91+G135/2-G151/2)+Assumptions!E281*(F103+F94/2+G132/2)+Assumptions!E282*(F104+G133/2-G149/2)+IF(G93+G102+G147=0,0,Assumptions!F279),0) -> 0 | H27: =ROUND(Assumptions!E280*(G91+H135/2-H151/2)+Assumptions!E281*(G103+G94/2+H132/2)+Assumptions!E282*(G104+H133/2-H149/2)+IF(H93+H102+H147=0,0,Assumptions!G279),0) -> 83 | I27: =ROUND(Assumptions!E280*(H91+I135/2-I151/2)+Assumptions!E281*(H103+H94/2+I132/2)+Assumptions!E282*(H104+I133/2-I149/2)+IF(I93+I102+I147=0,0,Assumptions!H279),0) -> 83 | J27: =ROUND(Assumptions!E280*(I91+J135/2-J151/2)+Assumptions!E281*(I103+I94/2+J132/2)+Assumptions!E282*(I104+J133/2-J149/2)+IF(J93+J102+J147=0,0,Assumptions!H279),0) -> 83 | K27: =ROUND(Assumptions!E280*(J91+K135/2-K151/2)+Assumptions!E281*(J103+J94/2+K132/2)+Assumptions!E282*(J104+K133/2-K149/2)+IF(K93+K102+K147=0,0,Assumptions!H279),0) -> 83 | L27: =ROUND(Assumptions!E280*(K91+L135/2-L151/2)+Assumptions!E281*(K103+K94/2+L132/2)+Assumptions!E282*(K104+L133/2-L149/2)+IF(L93+L102+L147=0,0,Assumptions!H279),0) -> 83 | M27: =ROUND(Assumptions!E280*(L91+M135/2-M151/2)+Assumptions!E281*(L103+L94/2+M132/2)+Assumptions!E282*(L104+M133/2-M149/2)+IF(M93+M102+M147=0,0,Assumptions!H279),0) -> 83 | N27: =ROUND(Assumptions!E280*(M91+N135/2-N151/2)+Assumptions!E281*(M103+M94/2+N132/2)+Assumptions!E282*(M104+N133/2-N149/2)+IF(N93+N102+N147=0,0,Assumptions!H279),0) -> 83 | O27: =ROUND(Assumptions!E280*(N91+O135/2-O151/2)+Assumptions!E281*(N103+N94/2+O132/2)+Assumptions!E282*(N104+O133/2-O149/2)+IF(O93+O102+O147=0,0,Assumptions!H279),0) -> 0 | P27: =ROUND(Assumptions!E280*(O91+P135/2-P151/2)+Assumptions!E281*(O103+O94/2+P132/2)+Assumptions!E282*(O104+P133/2-P149/2)+IF(P93+P102+P147=0,0,Assumptions!H279),0) -> 0 | Q27: =ROUND(Assumptions!E280*(P91+Q135/2-Q151/2)+Assumptions!E281*(P103+P94/2+Q132/2)+Assumptions!E282*(P104+Q133/2-Q149/2)+IF(Q93+Q102+Q147=0,0,Assumptions!H279),0) -> 0 | R27: =ROUND(Assumptions!E280*(Q91+R135/2-R151/2)+Assumptions!E281*(Q103+Q94/2+R132/2)+Assumptions!E282*(Q104+R133/2-R149/2)+IF(R93+R102+R147=0,0,Assumptions!H279),0) -> 0 | S27: =ROUND(Assumptions!E280*(R91+S135/2-S151/2)+Assumptions!E281*(R103+R94/2+S132/2)+Assumptions!E282*(R104+S133/2-S149/2)+IF(S93+S102+S147=0,0,Assumptions!H279),0) -> 0 | T27: =ROUND(Assumptions!E280*(S91+T135/2-T151/2)+Assumptions!E281*(S103+S94/2+T132/2)+Assumptions!E282*(S104+T133/2-T149/2)+IF(T93+T102+T147=0,0,Assumptions!H279),0) -> 0 | U27: =ROUND(Assumptions!E280*(T91+U135/2-U151/2)+Assumptions!E281*(T103+T94/2+U132/2)+Assumptions!E282*(T104+U133/2-U149/2)+IF(U93+U102+U147=0,0,Assumptions!H279),0) -> 0 | V27: =ROUND(Assumptions!E280*(U91+V135/2-V151/2)+Assumptions!E281*(U103+U94/2+V132/2)+Assumptions!E282*(U104+V133/2-V149/2)+IF(V93+V102+V147=0,0,Assumptions!H279),0) -> 0
A28: Other Exp. (Income)
A29: Other Exp. (Income) | B29: 0 | C29: 0 | D29: 0 | E29: 0 | F29: 0 | G29: 0 | H29: 0 | I29: 0 | J29: 0 | K29: 0 | L29: 0 | M29: 0 | N29: 0 | O29: 0 | P29: 0 | Q29: 0 | R29: 0 | S29: 0 | T29: 0 | U29: 0 | V29: 0
A31: Total Indirect Cost | B31: =ROUND(SUM(B25:B29),0) -> 0 | C31: =ROUND(SUM(C25:C29),0) -> 0 | D31: =ROUND(SUM(D25:D29),0) -> 0 | E31: =ROUND(SUM(E25:E29),0) -> 0 | F31: =ROUND(SUM(F25:F29),0) -> 0 | G31: =ROUND(SUM(G25:G29),0) -> 1913 | H31: =ROUND(SUM(H25:H29),0) -> 1996 | I31: =ROUND(SUM(I25:I29),0) -> 2527 | ... V31: =ROUND(SUM(V25:V29),0) -> 4161
A33: Profit Before Zakat | B33: =B22-B31 -> 0 | C33: =C22-C31 -> 0 | D33: =D22-D31 -> 0 | E33: =E22-E31 -> 0 | F33: =F22-F31 -> 0 | G33: =G22-G31 -> 5116 | H33: =H22-H31 -> 1653 | I33: =I22-I31 -> 2378 | ... V33: =V22-V31 -> 4361
A34: Zakat | G34: =ROUND(IF(G33>0,0.025*G33,0),0) -> 128 | H34: =ROUND(IF(H33>0,0.025*H33,0),0) -> 41 | I34: =ROUND(IF(I33>0,0.025*I33,0),0) -> 59 | J34: =ROUND(IF(J33>0,0.025*J33,0),0) -> 70 | K34: =ROUND(IF(K33>0,0.025*K33,0),0) -> 82 | L34: =ROUND(IF(L33>0,0.025*L33,0),0) -> 105 | M34: =ROUND(IF(M33>0,0.025*M33,0),0) -> 107 | N34: =ROUND(IF(N33>0,0.025*N33,0),0) -> 107 | ... V34: =ROUND(IF(V33>0,0.025*V33,0),0) -> 109
A36: Profit After Zakat | B36: =B33-B34 -> 0 | C36: =C33-C34 -> 0 | D36: =D33-D34 -> 0 | E36: =E33-E34 -> 0 | F36: =F33-F34 -> 0 | G36: =G33-G34 -> 4988 | H36: =H33-H34 -> 1612 | I36: =I33-I34 -> 2319 | ... V36: =V33-V34 -> 4252
A37: Satutory Reserve | G37: =IF(G121<G122,0.1*G185,G121-F115) -> 498.8 | H37: =IF(H121<H122,0.1*H185,H121-G115) -> 161.2 | I37: =IF(I121<I122,0.1*I185,I121-H115) -> 231.9 | J37: =IF(J121<J122,0.1*J185,J121-I115) -> 273.6 | K37: =IF(K121<K122,0.1*K185,K121-J115) -> 320.4 | L37: =IF(L121<L122,0.1*L185,L121-K115) -> 214.1 | M37: =IF(M121<M122,0.1*M185,M121-L115) -> 0 | N37: =IF(N121<N122,0.1*N185,N121-M115) -> 0 | ... V37: =IF(V121<V122,0.1*V185,V121-U115) -> 0
A38: Dividends | G38: =ROUND(G152,0) -> 0 | H38: =ROUND(H152,0) -> 0 | I38: =ROUND(I152,0) -> 0 | J38: =ROUND(J152,0) -> 0 | K38: =ROUND(K152,0) -> 0 | L38: =ROUND(L152,0) -> 0 | M38: =ROUND(M152,0) -> 5000 | N38: =ROUND(N152,0) -> 5000 | ... V38: =ROUND(V152,0) -> 8000
A39: Retained Earnings | B39: =B36-B38-B37 -> 0 | C39: =C36-C38-C37 -> 0 | D39: =D36-D38-D37 -> 0 | E39: =E36-E38-E37 -> 0 | F39: =F36-F38-F37 -> 0 | G39: =G36-G38-G37 -> 4489.2 | H39: =H36-H38-H37 -> 1450.8 | I39: =I36-I38-I37 -> 2087.1 | ... V39: =V36-V38-V37 -> -3748
K43: Balance Sheet- Assets | P43: Attachment B-2
R46: (SR in 000s)
C47: HISTORICAL | G47: PROJECTIONS
B48: =IF(B$6=0," ",B$6) | C48: =IF(C$6=0," ",C$6) | D48: =IF(D$6=0," ",D$6) | E48: =IF(E$6=0," ",E$6) | F48: =IF(F$6=0," ",F$6) | G48: =B318 -> 2025 | H48: =C318 -> 2026 | I48: =D318 -> 2027 | J48: =E318 -> 2028 | K48: =F318 -> 2029 | L48: =G318 -> 2030 | M48: =H318 -> 2031 | N48: =I318 -> 2032 | ... V48: =Q318 -> 2040
A50: Cash | G50: =ROUND(F50+G159,0) -> 149 | H50: =ROUND(G50+H159,0) -> 2649 | I50: =ROUND(H50+I159,0) -> 4872 | J50: =ROUND(I50+J159,0) -> 6748 | K50: =ROUND(J50+K159,0) -> 8719 | L50: =ROUND(K50+L159,0) -> 11087 | M50: =ROUND(L50+M159,0) -> 9688 | N50: =ROUND(M50+N159,0) -> 8089 | ... V50: =ROUND(U50+V159,0) -> 4145
A51: Accounts Receivable | G51: =ROUND(G8*Assumptions!F293/365,0) -> 4318 | H51: =ROUND(H8*Assumptions!F293/365,0) -> 3993 | I51: =ROUND(I8*Assumptions!G293/365,0) -> 4463 | J51: =ROUND(J8*Assumptions!H293/365,0) -> 5021 | K51: =ROUND(K8*Assumptions!I293/365,0) -> 5679 | L51: =ROUND(L8*Assumptions!J293/365,0) -> 6514 | M51: =ROUND(M8*Assumptions!J293/365,0) -> 6514 | N51: =ROUND(N8*Assumptions!J293/365,0) -> 6514 | O51: =ROUND(O8*Assumptions!J293/365,0) -> 6514 | P51: =ROUND(P8*Assumptions!J293/365,0) -> 6514 | Q51: =ROUND(Q8*Assumptions!J293/365,0) -> 6514 | R51: =ROUND(R8*Assumptions!J293/365,0) -> 6514 | S51: =ROUND(S8*Assumptions!J293/365,0) -> 6514 | T51: =ROUND(T8*Assumptions!J293/365,0) -> 6514 | U51: =ROUND(U8*Assumptions!J293/365,0) -> 6514 | V51: =ROUND(V8*Assumptions!J293/365,0) -> 6514
A52: Inventory | G52: =ROUND((G20-G15-G16)*Assumptions!F295/365,0) -> 3423 | H52: =ROUND((H20-H15-H16)*Assumptions!F295/365,0) -> 4059 | I52: =ROUND((I20-I15-I16)*Assumptions!G295/365,0) -> 4447 | J52: =ROUND((J20-J15-J16)*Assumptions!H295/365,0) -> 4925 | K52: =ROUND((K20-K15-K16)*Assumptions!I295/365,0) -> 5489 | L52: =ROUND((L20-L15-L16)*Assumptions!J295/365,0) -> 6199 | M52: =ROUND((M20-M15-M16)*Assumptions!J295/365,0) -> 6199 | N52: =ROUND((N20-N15-N16)*Assumptions!J295/365,0) -> 6199 | O52: =ROUND((O20-O15-O16)*Assumptions!J295/365,0) -> 6199 | P52: =ROUND((P20-P15-P16)*Assumptions!J295/365,0) -> 6199 | Q52: =ROUND((Q20-Q15-Q16)*Assumptions!J295/365,0) -> 6199 | R52: =ROUND((R20-R15-R16)*Assumptions!J295/365,0) -> 6199 | S52: =ROUND((S20-S15-S16)*Assumptions!J295/365,0) -> 6199 | T52: =ROUND((T20-T15-T16)*Assumptions!J295/365,0) -> 6199 | U52: =ROUND((U20-U15-U16)*Assumptions!J295/365,0) -> 6199 | V52: =ROUND((V20-V15-V16)*Assumptions!J295/365,0) -> 6199
A53: L/C Margins | G53: =ROUND(G11*Assumptions!F294/365,0) -> 0 | H53: =ROUND(H11*Assumptions!F294/365,0) -> 0 | I53: =ROUND(I11*Assumptions!G294/365,0) -> 0 | J53: =ROUND(J11*Assumptions!H294/365,0) -> 0 | K53: =ROUND(K11*Assumptions!I294/365,0) -> 0 | L53: =ROUND(L11*Assumptions!J294/365,0) -> 0 | M53: =ROUND(M11*Assumptions!J294/365,0) -> 0 | N53: =ROUND(N11*Assumptions!J294/365,0) -> 0 | O53: =ROUND(O11*Assumptions!J294/365,0) -> 0 | P53: =ROUND(P11*Assumptions!J294/365,0) -> 0 | Q53: =ROUND(Q11*Assumptions!J294/365,0) -> 0 | R53: =ROUND(R11*Assumptions!J294/365,0) -> 0 | S53: =ROUND(S11*Assumptions!J294/365,0) -> 0 | T53: =ROUND(T11*Assumptions!J294/365,0) -> 0 | U53: =ROUND(U11*Assumptions!J294/365,0) -> 0 | V53: =ROUND(V11*Assumptions!J294/365,0) -> 0
A54: Prepaid expenses and other current assests
A55: Dues from related parties
A57: Current Assets | B57: =ROUND(SUM(B50:B55),0) -> 0 | C57: =ROUND(SUM(C50:C55),0) -> 0 | D57: =ROUND(SUM(D50:D55),0) -> 0 | E57: =ROUND(SUM(E50:E55),0) -> 0 | F57: =ROUND(SUM(F50:F55),0) -> 0 | G57: =ROUND(SUM(G50:G55),0) -> 7890 | H57: =ROUND(SUM(H50:H55),0) -> 10701 | I57: =ROUND(SUM(I50:I55),0) -> 13782 | ... V57: =ROUND(SUM(V50:V55),0) -> 16858
...

Sheet Attachment "A"
A1: Attachment "A" | I1: Implementation Starting year | J1: 2024 | K1: To Be Filled If There is a Disbursement Through L/C | AC1: Yes | AD1: 2021
M2: =J1 -> 2024 | Q2: =M2+1 -> 2025 | AC2: No | AD2: 2022
K3: L/C? | L3: Amount SR '000 | M3: 1st Q | N3: 2nd Q | O3: 3rd Q | P3: 4th Q | Q3: 1st Q | R3: 2nd Q | S3: 3rd Q | T3: 4th Q | AD3: 2023
F4: SIDF Loan | G4: 0.39 | AD4: 2024
A5: Project Cost | AD5: 2025
A6: Items | D6: Total Projected | E6: Non Financeable | F6: Total Financeable | AD6: 2026
D7: SR '000 | AD7: 2027
A8: Land | D8: 0 | E8: 0 | F8: =D8-E8 -> 0 | AD8: 2028
A9: Building & Civil works | D9: =Assumptions!F227+Assumptions!G227 -> 770 | E9: 0 | F9: =D9-E9 -> 770 | M9: steps: 1- L/C?: choose Yes or No? 2- Amount: insert the amount of the LC 3- Choose which Quarter by Choosing Yes or No 4- Insert the amount under the chosen Quarter 5- It will be reflect directly on the liquidity needed table (row 40) | AD9: 2029
A10: Loss Prevention | D10: =Assumptions!F231+Assumptions!G231 -> 458 | E10: 0 | F10: =D10-E10 -> 458 | AD10: 2030
A11: Machinary & Equipment | D11: =Assumptions!F228+Assumptions!G228 -> 11353 | E11: 0 | F11: =D11-E11 -> 11353 | AD11: 2031
A12: Vehicles | D12: =Assumptions!F230+Assumptions!G230 -> 359 | E12: 0 | F12: =D12-E12 -> 359 | AD12: 2032
A13: Office Furniture | D13: =Assumptions!F229+Assumptions!G229 -> 0 | E13: 0 | F13: =D13-E13 -> 0 | AD13: 2033
A14: Funded Working Capital | D14: 0 | E14: 0 | F14: =D14-E14 -> 0 | AD14: 2034
A15: Pre-Operating Expenses | D15: =Assumptions!F237 -> 99 | E15: 0 | F15: =D15-E15 -> 99 | AD15: 2035
A16: Contingencies | D16: 0 | E16: 0 | F16: =D16-E16 -> 0 | AD16: 2036
A17: SIDF Evaluation Charges | D17: =Assumptions!F236+Assumptions!G236 -> 300 | E17: =D17 -> 300 | F17: =D17-E17 -> 0 | AD17: 2037
A18: Total Project Costs | D18: =SUM(D8:D17) -> 13339 | E18: =SUM(E8:E17) -> 300 | F18: =SUM(F8:F17) -> 13039 | AD18: 2038
A19: Source of Finance | AD19: 2039
A20: Items | AD20: 2040
A21: To be Financed by: | D21: % | E21: SR'000 | F21: Say | G21: % Of Project Cost | AD21: 2040
A22: SIDF Loan | D22: =IF(F22=0,"0",F22/$F$26) -> 0.37484069 | E22: =ROUND(G4*F18,0) -> 5085 | F22: =ROUNDDOWN(E22,-2) -> 5000 | G22: =F22/F26 -> 0.37484069
A23: Paid in Capital | D23: =IF(F23=0,"0",F23/$F$26) -> 0.25489167 | E23: =D18*0.25 -> 3334.75 | F23: =ROUNDUP(E23,-2) -> 3400 | G23: =F23/F26 -> 0.25489167
A24: Internally Generated Fund | D24: =IF(F24=0,"0",F24/$F$26) -> 0.37026764 | E24: =D18-F23-F22 -> 4939 | F24: =E24 -> 4939 | G24: =F24/F26 -> 0.37026764
D25: =IF(F25=0,"0",F25/$F$26) -> 0 | E25: 0 | F25: =E25 -> 0 | G25: =F25/F26 -> 0
A26: Total | D26: =SUM(D22:D25) -> 1 | F26: =SUM(F22:F25) -> 13339
A28: Implementation Status | M28: 1- Insert the % of implementation completion for each category under each Quarter 2-The cumulative completion % of each category should not exceed 100% (check column j) 3- M&E % completion should not include any L/C in the Implementation status table as it should be reflected in the L/C table above
B29: =J1 -> 2024 | F29: =B29+1 -> 2025 | J29: completion %
A30: % | B30: 1st Q | C30: 2nd Q | D30: 3rd Q | E30: 4th Q | F30: 1st Q | G30: 2nd Q | H30: 3rd Q | I30: 4th Q
A31: Items
A32: Building & Civil works | B32: 0.3 | C32: 0.4 | D32: 0.3 | J32: =SUM(B32:I32) -> 1
A33: Loss Prevention | D33: 0.4 | E33: 0.6 | J33: =SUM(B33:I33) -> 1
A34: Machinary & Equipment | C34: 0.3 | D34: 0.3 | E34: 0.4 | J34: =SUM(B34:I34) -> 1
A35: Vehicles | D35: 0.5 | E35: 0.5 | J35: =SUM(B35:I35) -> 1
A36: Office Furniture | E36: 0.5 | F36: 0.5 | J36: =SUM(B36:I36) -> 1 | N36: To validate the following: 1- SIDF loan (row 44) should not exceed the approved loan amount minus Evaluation fees 2- L/C amount (row 45) should not exceed the approved loan amount. If there is no LC the row should be colored black and if there is an LC it will automatically be reflected from the LC table above 3- Evaluation Cost (row 46) should not exceed the approved Evaluation cost 4- The sum of SIDF loan, L/C and Evaluation Cost should not exceed the approved Loan amount 5- Total SIDF disbursements should be equal to SIDF loan minus SIDF evaluation Cost
A37: Funded Working Capital | J37: =SUM(B37:I37) -> 0
A38: Pre-Operating Expenses | D38: 0.3 | E38: 0.7 | J38: =SUM(B38:I38) -> 1
A39: Contingencies | J39: =SUM(B39:I39) -> 0
A41: Liquidity Needed (Automatically Filled)
A42: SR '000 | B42: =B29 -> 2024 | F42: =F29 -> 2025 | K42: Valdiation
...

Sheet IS
A1: Year | B1: =#REF! -> #REF! | C1: =#REF! -> #REF! | D1: =#REF! -> #REF! | E1: =#REF! -> #REF! | F1: =#REF! -> #REF! | G1: =#REF! -> #REF! | H1: =#REF! -> #REF! | I1: =#REF! -> #REF! | ... Q1: =#REF! -> #REF!
A2: Sales | B2: =#REF!*1000 -> #REF! | C2: =#REF!*1000 -> #REF! | D2: =#REF!*1000 -> #REF! | E2: =#REF!*1000 -> #REF! | F2: =#REF!*1000 -> #REF! | G2: =#REF!*1000 -> #REF! | H2: =#REF!*1000 -> #REF! | I2: =#REF!*1000 -> #REF! | ... Q2: =#REF!*1000 -> #REF!
A3: Rawmat | B3: =#REF!*1000 -> #REF! | C3: =#REF!*1000 -> #REF! | D3: =#REF!*1000 -> #REF! | E3: =#REF!*1000 -> #REF! | F3: =#REF!*1000 -> #REF! | G3: =#REF!*1000 -> #REF! | H3: =#REF!*1000 -> #REF! | I3: =#REF!*1000 -> #REF! | ... Q3: =#REF!*1000 -> #REF!
A4: Dirlab | B4: =#REF!*1000 -> #REF! | C4: =#REF!*1000 -> #REF! | D4: =#REF!*1000 -> #REF! | E4: =#REF!*1000 -> #REF! | F4: =#REF!*1000 -> #REF! | G4: =#REF!*1000 -> #REF! | H4: =#REF!*1000 -> #REF! | I4: =#REF!*1000 -> #REF! | ... Q4: =#REF!*1000 -> #REF!
A5: Utils | B5: =#REF!*1000 -> #REF! | C5: =#REF!*1000 -> #REF! | D5: =#REF!*1000 -> #REF! | E5: =#REF!*1000 -> #REF! | F5: =#REF!*1000 -> #REF! | G5: =#REF!*1000 -> #REF! | H5: =#REF!*1000 -> #REF! | I5: =#REF!*1000 -> #REF! | ... Q5: =#REF!*1000 -> #REF!
A6: Maint | B6: =#REF!*1000 -> #REF! | C6: =#REF!*1000 -> #REF! | D6: =#REF!*1000 -> #REF! | E6: =#REF!*1000 -> #REF! | F6: =#REF!*1000 -> #REF! | G6: =#REF!*1000 -> #REF! | H6: =#REF!*1000 -> #REF! | I6: =#REF!*1000 -> #REF! | ... Q6: =#REF!*1000 -> #REF!
A7: Deprec | B7: =#REF!*1000 -> #REF! | C7: =#REF!*1000 -> #REF! | D7: =#REF!*1000 -> #REF! | E7: =#REF!*1000 -> #REF! | F7: =#REF!*1000 -> #REF! | G7: =#REF!*1000 -> #REF! | H7: =#REF!*1000 -> #REF! | I7: =#REF!*1000 -> #REF! | ... Q7: =#REF!*1000 -> #REF!
A8: Amort | B8: =#REF!*1000 -> #REF! | C8: =#REF!*1000 -> #REF! | D8: =#REF!*1000 -> #REF! | E8: =#REF!*1000 -> #REF! | F8: =#REF!*1000 -> #REF! | G8: =#REF!*1000 -> #REF! | H8: =#REF!*1000 -> #REF! | I8: =#REF!*1000 -> #REF! | ... Q8: =#REF!*1000 -> #REF!
A9: Othdirexp | B9: =#REF!*1000 -> #REF! | C9: =#REF!*1000 -> #REF! | D9: =#REF!*1000 -> #REF! | E9: =#REF!*1000 -> #REF! | F9: =#REF!*1000 -> #REF! | G9: =#REF!*1000 -> #REF! | H9: =#REF!*1000 -> #REF! | I9: =#REF!*1000 -> #REF! | ... Q9: =#REF!*1000 -> #REF!
A10: Cgs | B10: =#REF!*1000 -> #REF! | C10: =#REF!*1000 -> #REF! | D10: =#REF!*1000 -> #REF! | E10: =#REF!*1000 -> #REF! | F10: =#REF!*1000 -> #REF! | G10: =#REF!*1000 -> #REF! | H10: =#REF!*1000 -> #REF! | I10: =#REF!*1000 -> #REF! | ... Q10: =#REF!*1000 -> #REF!
A11: Grossmar | B11: =#REF!*1000 -> #REF! | C11: =#REF!*1000 -> #REF! | D11: =#REF!*1000 -> #REF! | E11: =#REF!*1000 -> #REF! | F11: =#REF!*1000 -> #REF! | G11: =#REF!*1000 -> #REF! | H11: =#REF!*1000 -> #REF! | I11: =#REF!*1000 -> #REF! | ... Q11: =#REF!*1000 -> #REF!
A12: Salesad | B12: =#REF!*1000 -> #REF! | C12: =#REF!*1000 -> #REF! | D12: =#REF!*1000 -> #REF! | E12: =#REF!*1000 -> #REF! | F12: =#REF!*1000 -> #REF! | G12: =#REF!*1000 -> #REF! | H12: =#REF!*1000 -> #REF! | I12: =#REF!*1000 -> #REF! | ... Q12: =#REF!*1000 -> #REF!
A13: Salar | B13: =#REF!*1000 -> #REF! | C13: =#REF!*1000 -> #REF! | D13: =#REF!*1000 -> #REF! | E13: =#REF!*1000 -> #REF! | F13: =#REF!*1000 -> #REF! | G13: =#REF!*1000 -> #REF! | H13: =#REF!*1000 -> #REF! | I13: =#REF!*1000 -> #REF! | ... Q13: =#REF!*1000 -> #REF!
... A22: Retear | B22: =#REF!*1000 -> #REF! | C22: =#REF!*1000 -> #REF! | D22: =#REF!*1000 -> #REF! | E22: =#REF!*1000 -> #REF! | F22: =#REF!*1000 -> #REF! | G22: =#REF!*1000 -> #REF! | H22: =#REF!*1000 -> #REF! | I22: =#REF!*1000 -> #REF! | ... Q22: =#REF!*1000 -> #REF!

Sheet BSA
A1: Year | B1: =#REF! -> #REF! | C1: =#REF! -> #REF! | D1: =#REF! -> #REF! | E1: =#REF! -> #REF! | F1: =#REF! -> #REF! | G1: =#REF! -> #REF! | H1: =#REF! -> #REF! | I1: =#REF! -> #REF! | ... Q1: =#REF! -> #REF!
A2: Factorycash | B2: =#REF!*1000 -> #REF! | C2: =#REF!*1000 -> #REF! | D2: =#REF!*1000 -> #REF! | E2: =#REF!*1000 -> #REF! | F2: =#REF!*1000 -> #REF! | G2: =#REF!*1000 -> #REF! | H2: =#REF!*1000 -> #REF! | I2: =#REF!*1000 -> #REF! | ... Q2: =#REF!*1000 -> #REF!
A3: Accntsrec | B3: =#REF!*1000 -> #REF! | C3: =#REF!*1000 -> #REF! | D3: =#REF!*1000 -> #REF! | E3: =#REF!*1000 -> #REF! | F3: =#REF!*1000 -> #REF! | G3: =#REF!*1000 -> #REF! | H3: =#REF!*1000 -> #REF! | I3: =#REF!*1000 -> #REF! | ... Q3: =#REF!*1000 -> #REF!
A4: Inventory | B4: =#REF!*1000 -> #REF! | C4: =#REF!*1000 -> #REF! | D4: =#REF!*1000 -> #REF! | E4: =#REF!*1000 -> #REF! | F4: =#REF!*1000 -> #REF! | G4: =#REF!*1000 -> #REF! | H4: =#REF!*1000 -> #REF! | I4: =#REF!*1000 -> #REF! | ... Q4: =#REF!*1000 -> #REF!
A5: Lcmargins | B5: =#REF!*1000 -> #REF! | C5: =#REF!*1000 -> #REF! | D5: =#REF!*1000 -> #REF! | E5: =#REF!*1000 -> #REF! | F5: =#REF!*1000 -> #REF! | G5: =#REF!*1000 -> #REF! | H5: =#REF!*1000 -> #REF! | I5: =#REF!*1000 -> #REF! | ... Q5: =#REF!*1000 -> #REF!
A6: Prepaid | B6: =#REF!*1000 -> #REF! | C6: =#REF!*1000 -> #REF! | D6: =#REF!*1000 -> #REF! | E6: =#REF!*1000 -> #REF! | F6: =#REF!*1000 -> #REF! | G6: =#REF!*1000 -> #REF! | H6: =#REF!*1000 -> #REF! | I6: =#REF!*1000 -> #REF! | ... Q6: =#REF!*1000 -> #REF!
A7: Other1 | B7: =#REF!*1000 -> #REF! | C7: =#REF!*1000 -> #REF! | D7: =#REF!*1000 -> #REF! | E7: =#REF!*1000 -> #REF! | F7: =#REF!*1000 -> #REF! | G7: =#REF!*1000 -> #REF! | H7: =#REF!*1000 -> #REF! | I7: =#REF!*1000 -> #REF! | ... Q7: =#REF!*1000 -> #REF!
A8: Currentassets | B8: =#REF!*1000 -> #REF! | C8: =#REF!*1000 -> #REF! | D8: =#REF!*1000 -> #REF! | E8: =#REF!*1000 -> #REF! | F8: =#REF!*1000 -> #REF! | G8: =#REF!*1000 -> #REF! | H8: =#REF!*1000 -> #REF! | I8: =#REF!*1000 -> #REF! | ... Q8: =#REF!*1000 -> #REF!
A9: Land | B9: =#REF!*1000 -> #REF! | C9: =#REF!*1000 -> #REF! | D9: =#REF!*1000 -> #REF! | E9: =#REF!*1000 -> #REF! | F9: =#REF!*1000 -> #REF! | G9: =#REF!*1000 -> #REF! | H9: =#REF!*1000 -> #REF! | I9: =#REF!*1000 -> #REF! | ... Q9: =#REF!*1000 -> #REF!
A10: Buildings | B10: =#REF!*1000 -> #REF! | C10: =#REF!*1000 -> #REF! | D10: =#REF!*1000 -> #REF! | E10: =#REF!*1000 -> #REF! | F10: =#REF!*1000 -> #REF! | G10: =#REF!*1000 -> #REF! | H10: =#REF!*1000 -> #REF! | I10: =#REF!*1000 -> #REF! | ... Q10: =#REF!*1000 -> #REF!
A11: Machinery | B11: =#REF!*1000 -> #REF! | C11: =#REF!*1000 -> #REF! | D11: =#REF!*1000 -> #REF! | E11: =#REF!*1000 -> #REF! | F11: =#REF!*1000 -> #REF! | G11: =#REF!*1000 -> #REF! | H11: =#REF!*1000 -> #REF! | I11: =#REF!*1000 -> #REF! | ... Q11: =#REF!*1000 -> #REF!
A12: Furniture | B12: =#REF!*1000 -> #REF! | C12: =#REF!*1000 -> #REF! | D12: =#REF!*1000 -> #REF! | E12: =#REF!*1000 -> #REF! | F12: =#REF!*1000 -> #REF! | G12: =#REF!*1000 -> #REF! | H12: =#REF!*1000 -> #REF! | I12: =#REF!*1000 -> #REF! | ... Q12: =#REF!*1000 -> #REF!
A13: Vehicles | B13: =#REF!*1000 -> #REF! | C13: =#REF!*1000 -> #REF! | D13: =#REF!*1000 -> #REF! | E13: =#REF!*1000 -> #REF! | F13: =#REF!*1000 -> #REF! | G13: =#REF!*1000 -> #REF! | H13: =#REF!*1000 -> #REF! | I13: =#REF!*1000 -> #REF! | ... Q13: =#REF!*1000 -> #REF!
... A26: Totassets | B26: =#REF!*1000 -> #REF! | C26: =#REF!*1000 -> #REF! | D26: =#REF!*1000 -> #REF! | E26: =#REF!*1000 -> #REF! | F26: =#REF!*1000 -> #REF! | G26: =#REF!*1000 -> #REF! | H26: =#REF!*1000 -> #REF! | I26: =#REF!*1000 -> #REF! | ... Q26: =#REF!*1000 -> #REF!

Sheet BSL
A1: Year | B1: =#REF! -> #REF! | C1: =#REF! -> #REF! | D1: =#REF! -> #REF! | E1: =#REF! -> #REF! | F1: =#REF! -> #REF! | G1: =#REF! -> #REF! | H1: =#REF! -> #REF! | I1: =#REF! -> #REF! | ... Q1: =#REF! -> #REF!
A2: Acpay | B2: =#REF!*1000 -> #REF! | C2: =#REF!*1000 -> #REF! | D2: =#REF!*1000 -> #REF! | E2: =#REF!*1000 -> #REF! | F2: =#REF!*1000 -> #REF! | G2: =#REF!*1000 -> #REF! | H2: =#REF!*1000 -> #REF! | I2: =#REF!*1000 -> #REF! | ... Q2: =#REF!*1000 -> #REF!
A3: Std | B3: =#REF!*1000 -> #REF! | C3: =#REF!*1000 -> #REF! | D3: =#REF!*1000 -> #REF! | E3: =#REF!*1000 -> #REF! | F3: =#REF!*1000 -> #REF! | G3: =#REF!*1000 -> #REF! | H3: =#REF!*1000 -> #REF! | I3: =#REF!*1000 -> #REF! | ... Q3: =#REF!*1000 -> #REF!
A4: Accruals | B4: =#REF!*1000 -> #REF! | C4: =#REF!*1000 -> #REF! | D4: =#REF!*1000 -> #REF! | E4: =#REF!*1000 -> #REF! | F4: =#REF!*1000 -> #REF! | G4: =#REF!*1000 -> #REF! | H4: =#REF!*1000 -> #REF! | I4: =#REF!*1000 -> #REF! | ... Q4: =#REF!*1000 -> #REF!
A5: Cplsidf | B5: =#REF!*1000 -> #REF! | C5: =#REF!*1000 -> #REF! | D5: =#REF!*1000 -> #REF! | E5: =#REF!*1000 -> #REF! | F5: =#REF!*1000 -> #REF! | G5: =#REF!*1000 -> #REF! | H5: =#REF!*1000 -> #REF! | I5: =#REF!*1000 -> #REF! | ... Q5: =#REF!*1000 -> #REF!
A6: Cplbank | B6: =#REF!*1000 -> #REF! | C6: =#REF!*1000 -> #REF! | D6: =#REF!*1000 -> #REF! | E6: =#REF!*1000 -> #REF! | F6: =#REF!*1000 -> #REF! | G6: =#REF!*1000 -> #REF! | H6: =#REF!*1000 -> #REF! | I6: =#REF!*1000 -> #REF! | ... Q6: =#REF!*1000 -> #REF!
A7: Cplother | B7: =#REF!*1000 -> #REF! | C7: =#REF!*1000 -> #REF! | D7: =#REF!*1000 -> #REF! | E7: =#REF!*1000 -> #REF! | F7: =#REF!*1000 -> #REF! | G7: =#REF!*1000 -> #REF! | H7: =#REF!*1000 -> #REF! | I7: =#REF!*1000 -> #REF! | ... Q7: =#REF!*1000 -> #REF!
A8: Other1 | B8: =#REF!*1000 -> #REF! | C8: =#REF!*1000 -> #REF! | D8: =#REF!*1000 -> #REF! | E8: =#REF!*1000 -> #REF! | F8: =#REF!*1000 -> #REF! | G8: =#REF!*1000 -> #REF! | H8: =#REF!*1000 -> #REF! | I8: =#REF!*1000 -> #REF! | ... Q8: =#REF!*1000 -> #REF!
A9: Other2 | B9: =#REF!*1000 -> #REF! | C9: =#REF!*1000 -> #REF! | D9: =#REF!*1000 -> #REF! | E9: =#REF!*1000 -> #REF! | F9: =#REF!*1000 -> #REF! | G9: =#REF!*1000 -> #REF! | H9: =#REF!*1000 -> #REF! | I9: =#REF!*1000 -> #REF! | ... Q9: =#REF!*1000 -> #REF!
A10: Currentliab | B10: =#REF!*1000 -> #REF! | C10: =#REF!*1000 -> #REF! | D10: =#REF!*1000 -> #REF! | E10: =#REF!*1000 -> #REF! | F10: =#REF!*1000 -> #REF! | G10: =#REF!*1000 -> #REF! | H10: =#REF!*1000 -> #REF! | I10: =#REF!*1000 -> #REF! | ... Q10: =#REF!*1000 -> #REF!
A11: Ltdsidf | B11: =#REF!*1000 -> #REF! | C11: =#REF!*1000 -> #REF! | D11: =#REF!*1000 -> #REF! | E11: =#REF!*1000 -> #REF! | F11: =#REF!*1000 -> #REF! | G11: =#REF!*1000 -> #REF! | H11: =#REF!*1000 -> #REF! | I11: =#REF!*1000 -> #REF! | ... Q11: =#REF!*1000 -> #REF!
A12: Ltdbank | B12: =#REF!*1000 -> #REF! | C12: =#REF!*1000 -> #REF! | D12: =#REF!*1000 -> #REF! | E12: =#REF!*1000 -> #REF! | F12: =#REF!*1000 -> #REF! | G12: =#REF!*1000 -> #REF! | H12: =#REF!*1000 -> #REF! | I12: =#REF!*1000 -> #REF! | ... Q12: =#REF!*1000 -> #REF!
A13: Ltdother | B13: =#REF!*1000 -> #REF! | C13: =#REF!*1000 -> #REF! | D13: =#REF!*1000 -> #REF! | E13: =#REF!*1000 -> #REF! | F13: =#REF!*1000 -> #REF! | G13: =#REF!*1000 -> #REF! | H13: =#REF!*1000 -> #REF! | I13: =#REF!*1000 -> #REF! | ... Q13: =#REF!*1000 -> #REF!
... A23: Totliabeq | B23: =#REF!*1000 -> #REF! | C23: =#REF!*1000 -> #REF! | D23: =#REF!*1000 -> #REF! | E23: =#REF!*1000 -> #REF! | F23: =#REF!*1000 -> #REF! | G23: =#REF!*1000 -> #REF! | H23: =#REF!*1000 -> #REF! | I23: =#REF!*1000 -> #REF! | ... Q23: =#REF!*1000 -> #REF!

Sheet SA
A1: =SUBSTITUTE(TRIM(#REF!)," ","") -> #REF! | B1: =#REF! -> #REF! | C1: =#REF! -> #REF!
A2: =SUBSTITUTE(TRIM(#REF!)," ","") -> #REF! | B2: =#REF! -> #REF! | C2: =#REF! -> #REF!
A3: =SUBSTITUTE(TRIM(#REF!)," ","") -> #REF! | B3: =#REF! -> #REF! | C3: =#REF! -> #REF!
